<?xml version="1.0" ?>
<!-- =================================================================================== -->
<!-- |    This document was autogenerated by xacro from /home/kaiser/WS_ROS/ws_tfg/src/serpiente/serpiente_description/urdf/serpiente_larga.xacro | -->
<!-- |    EDITING THIS FILE BY HAND IS NOT RECOMMENDED                                 | -->
<!-- =================================================================================== -->
<robot name="serp" xmlns:xacro="http://www.ros.org/wiki/xacro">
  <link name="map">
  </link>
  <gazebo>
    <plugin filename="libgazebo_ros_control.so" name="gazebo_ros_control">
      <robotNamespace>/serp</robotNamespace>
    </plugin>
  </gazebo>
  <joint name="map" type="fixed">
    <origin rpy="0 0 0" xyz="0.01 0 0"/>
    <parent link="map"/>
    <child link="base_link1"/>
  </joint>
  <link name="base_link1">
    <inertial>
      <origin rpy="0 0 0" xyz="0.04 0 -0.0015809"/>
      <mass value="0.2"/>
      <inertia ixx="0.033333" ixy="7.6472E-21" ixz="-1.039E-21" iyy="0.017333" iyz="2.322E-21" izz="0.017333"/>
    </inertial>
    <visual>
      <origin rpy="0 0 0" xyz="0 0 0"/>
      <geometry>
        <mesh filename="package://serpiente_description/urdf/meshes_serpiente/base_link.stl"/>
        <!-- <mesh filename="file:///home/kaiser/catkin_ws_CromaBueno/src/croma_description/meshes/base_link.stl" /> -->
      </geometry>
      <material name="">
        <color rgba="0.79216 0 0.93333 1"/>
      </material>
    </visual>
    <collision>
      <origin rpy="0 0 0" xyz="0 0 0"/>
      <geometry>
        <mesh filename="package://serpiente_description/urdf/meshes_serpiente/base_link.stl"/>
      </geometry>
    </collision>
  </link>
  <link name="cilinder1">
    <inertial>
      <origin rpy="0 0 0" xyz="0.08 2.7756E-17 1.3293E-50"/>
      <mass value="0.7854"/>
      <inertia ixx="0.011454" ixy="2.2588E-20" ixz="3.7494E-36" iyy="0.0098175" iyz="3.7944E-36" izz="0.011454"/>
    </inertial>
    <visual>
      <origin rpy="0 0 0" xyz="0 0 0"/>
      <geometry>
        <mesh filename="package://serpiente_description/urdf/meshes_serpiente/cilinder.stl"/>
      </geometry>
      <material name="">
        <color rgba="1 0 0 1"/>
      </material>
    </visual>
    <collision>
      <origin rpy="0 0 0" xyz="0 0 0"/>
      <geometry>
        <mesh filename="package://serpiente_description/urdf/meshes_serpiente/cilinder.stl"/>
      </geometry>
    </collision>
  </link>
  <joint name="base_cilinder_joint1" type="fixed">
    <origin rpy="0 0 0" xyz="0 0 0"/>
    <parent link="base_link1"/>
    <child link="cilinder1"/>
    <axis xyz="0 0 0"/>
  </joint>
  <link name="blue_box1">
    <inertial>
      <origin rpy="0 0 0" xyz="0.04 0 2.0668E-19"/>
      <mass value="0.2"/>
      <inertia ixx="0.033333" ixy="3.4121E-21" ixz="-1.3214E-21" iyy="0.017333" iyz="2.322E-21" izz="0.017333"/>
    </inertial>
    <visual>
      <origin rpy="0 0 0" xyz="0 0 0"/>
      <geometry>
        <mesh filename="package://serpiente_description/urdf/meshes_serpiente/blue_box.stl"/>
      </geometry>
      <material name="">
        <color rgba="0 0 1 1"/>
      </material>
    </visual>
    <collision>
      <origin rpy="0 0 0" xyz="0 0 0"/>
      <geometry>
        <mesh filename="package://serpiente_description/urdf/meshes_serpiente/blue_box.stl"/>
      </geometry>
    </collision>
  </link>
  <joint name="box_cilinder_joint1" type="revolute">
    <origin rpy="0 0 0" xyz="0.05 0 0"/>
    <parent link="cilinder1"/>
    <child link="blue_box1"/>
    <axis xyz="0 1 0"/>
    <limit effort="100" lower="-2.5" upper="2.5" velocity="1000"/>
  </joint>
  <gazebo reference="base_link1">
    <material>Gazebo/Green</material>
  </gazebo>
  <gazebo reference="cilinder1">
    <material>Gazebo/Green</material>
  </gazebo>
  <gazebo reference="blue_box1">
    <material>Gazebo/Green</material>
  </gazebo>
  <transmission name="t_box_cilinder_joint1">
    <type>transmission_interface/SimpleTransmission</type>
    <joint name="box_cilinder_joint1">
      <hardwareInterface>EffortJointInterface</hardwareInterface>
    </joint>
    <actuator name="m_box_cilinder_joint1">
      <hardwareInterface>EffortJointInterface</hardwareInterface>
      <mechanicalReduction>1</mechanicalReduction>
    </actuator>
  </transmission>
  <joint name="blue_box1" type="fixed">
    <origin rpy="0 0 0" xyz="0.05 0 0"/>
    <parent link="blue_box1"/>
    <child link="base_link2"/>
  </joint>
  <link name="base_link2">
    <inertial>
      <origin rpy="0 0 0" xyz="0.08 0 -0.0015809"/>
      <mass value="0.2"/>
      <inertia ixx="0.033333" ixy="7.6472E-21" ixz="-1.039E-21" iyy="0.017333" iyz="2.322E-21" izz="0.017333"/>
    </inertial>
    <visual>
      <origin rpy="0 0 0" xyz="0 0 0"/>
      <geometry>
        <mesh filename="package://serpiente_description/urdf/meshes_serpiente/base_link.stl"/>
        <!-- <mesh filename="file:///home/kaiser/catkin_ws_CromaBueno/src/croma_description/meshes/base_link.stl" /> -->
      </geometry>
      <material name="">
        <color rgba="0.79216 0 0.93333 1"/>
      </material>
    </visual>
    <collision>
      <origin rpy="0 0 0" xyz="0 0 0"/>
      <geometry>
        <mesh filename="package://serpiente_description/urdf/meshes_serpiente/base_link.stl"/>
      </geometry>
    </collision>
  </link>
  <link name="cilinder2">
    <inertial>
      <origin rpy="0 0 0" xyz="0.12 2.7756E-17 1.3293E-50"/>
      <mass value="0.7854"/>
      <inertia ixx="0.011454" ixy="2.2588E-20" ixz="3.7494E-36" iyy="0.0098175" iyz="3.7944E-36" izz="0.011454"/>
    </inertial>
    <visual>
      <origin rpy="0 0 0" xyz="0 0 0"/>
      <geometry>
        <mesh filename="package://serpiente_description/urdf/meshes_serpiente/cilinder.stl"/>
      </geometry>
      <material name="">
        <color rgba="1 0 0 1"/>
      </material>
    </visual>
    <collision>
      <origin rpy="0 0 0" xyz="0 0 0"/>
      <geometry>
        <mesh filename="package://serpiente_description/urdf/meshes_serpiente/cilinder.stl"/>
      </geometry>
    </collision>
  </link>
  <joint name="base_cilinder_joint2" type="fixed">
    <origin rpy="1.57079632679 0 0" xyz="0 0 0"/>
    <parent link="base_link2"/>
    <child link="cilinder2"/>
    <axis xyz="0 0 0"/>
  </joint>
  <link name="blue_box2">
    <inertial>
      <origin rpy="0 0 0" xyz="0.04 0 2.0668E-19"/>
      <mass value="0.2"/>
      <inertia ixx="0.033333" ixy="3.4121E-21" ixz="-1.3214E-21" iyy="0.017333" iyz="2.322E-21" izz="0.017333"/>
    </inertial>
    <visual>
      <origin rpy="0 0 0" xyz="0 0 0"/>
      <geometry>
        <mesh filename="package://serpiente_description/urdf/meshes_serpiente/blue_box.stl"/>
      </geometry>
      <material name="">
        <color rgba="0 0 1 1"/>
      </material>
    </visual>
    <collision>
      <origin rpy="0 0 0" xyz="0 0 0"/>
      <geometry>
        <mesh filename="package://serpiente_description/urdf/meshes_serpiente/blue_box.stl"/>
      </geometry>
    </collision>
  </link>
  <joint name="box_cilinder_joint2" type="revolute">
    <origin rpy="0 0 0" xyz="0.05 0 0"/>
    <parent link="cilinder2"/>
    <child link="blue_box2"/>
    <axis xyz="0 1 0"/>
    <limit effort="100" lower="-2.5" upper="2.5" velocity="1000"/>
  </joint>
  <gazebo reference="base_link2">
    <material>Gazebo/Green</material>
  </gazebo>
  <gazebo reference="cilinder2">
    <material>Gazebo/Green</material>
  </gazebo>
  <gazebo reference="blue_box2">
    <material>Gazebo/Green</material>
  </gazebo>
  <transmission name="t_box_cilinder_joint2">
    <type>transmission_interface/SimpleTransmission</type>
    <joint name="box_cilinder_joint2">
      <hardwareInterface>EffortJointInterface</hardwareInterface>
    </joint>
    <actuator name="m_box_cilinder_joint2">
      <hardwareInterface>EffortJointInterface</hardwareInterface>
      <mechanicalReduction>1</mechanicalReduction>
    </actuator>
  </transmission>
  <joint name="blue_box2" type="fixed">
    <origin rpy="0 0 0" xyz="0.05 0 0"/>
    <parent link="blue_box2"/>
    <child link="base_link3"/>
  </joint>
  <link name="base_link3">
    <inertial>
      <origin rpy="0 0 0" xyz="0.08 0 -0.0015809"/>
      <mass value="0.2"/>
      <inertia ixx="0.033333" ixy="7.6472E-21" ixz="-1.039E-21" iyy="0.017333" iyz="2.322E-21" izz="0.017333"/>
    </inertial>
    <visual>
      <origin rpy="0 0 0" xyz="0 0 0"/>
      <geometry>
        <mesh filename="package://serpiente_description/urdf/meshes_serpiente/base_link.stl"/>
        <!-- <mesh filename="file:///home/kaiser/catkin_ws_CromaBueno/src/croma_description/meshes/base_link.stl" /> -->
      </geometry>
      <material name="">
        <color rgba="0.79216 0 0.93333 1"/>
      </material>
    </visual>
    <collision>
      <origin rpy="0 0 0" xyz="0 0 0"/>
      <geometry>
        <mesh filename="package://serpiente_description/urdf/meshes_serpiente/base_link.stl"/>
      </geometry>
    </collision>
  </link>
  <link name="cilinder3">
    <inertial>
      <origin rpy="0 0 0" xyz="0.12 2.7756E-17 1.3293E-50"/>
      <mass value="0.7854"/>
      <inertia ixx="0.011454" ixy="2.2588E-20" ixz="3.7494E-36" iyy="0.0098175" iyz="3.7944E-36" izz="0.011454"/>
    </inertial>
    <visual>
      <origin rpy="0 0 0" xyz="0 0 0"/>
      <geometry>
        <mesh filename="package://serpiente_description/urdf/meshes_serpiente/cilinder.stl"/>
      </geometry>
      <material name="">
        <color rgba="1 0 0 1"/>
      </material>
    </visual>
    <collision>
      <origin rpy="0 0 0" xyz="0 0 0"/>
      <geometry>
        <mesh filename="package://serpiente_description/urdf/meshes_serpiente/cilinder.stl"/>
      </geometry>
    </collision>
  </link>
  <joint name="base_cilinder_joint3" type="fixed">
    <origin rpy="-1.57079632679 0 0" xyz="0 0 0"/>
    <parent link="base_link3"/>
    <child link="cilinder3"/>
    <axis xyz="0 0 0"/>
  </joint>
  <link name="blue_box3">
    <inertial>
      <origin rpy="0 0 0" xyz="0.04 0 2.0668E-19"/>
      <mass value="0.2"/>
      <inertia ixx="0.033333" ixy="3.4121E-21" ixz="-1.3214E-21" iyy="0.017333" iyz="2.322E-21" izz="0.017333"/>
    </inertial>
    <visual>
      <origin rpy="0 0 0" xyz="0 0 0"/>
      <geometry>
        <mesh filename="package://serpiente_description/urdf/meshes_serpiente/blue_box.stl"/>
      </geometry>
      <material name="">
        <color rgba="0 0 1 1"/>
      </material>
    </visual>
    <collision>
      <origin rpy="0 0 0" xyz="0 0 0"/>
      <geometry>
        <mesh filename="package://serpiente_description/urdf/meshes_serpiente/blue_box.stl"/>
      </geometry>
    </collision>
  </link>
  <joint name="box_cilinder_joint3" type="revolute">
    <origin rpy="0 0 0" xyz="0.05 0 0"/>
    <parent link="cilinder3"/>
    <child link="blue_box3"/>
    <axis xyz="0 1 0"/>
    <limit effort="100" lower="-2.5" upper="2.5" velocity="1000"/>
  </joint>
  <gazebo reference="base_link3">
    <material>Gazebo/Green</material>
  </gazebo>
  <gazebo reference="cilinder3">
    <material>Gazebo/Green</material>
  </gazebo>
  <gazebo reference="blue_box3">
    <material>Gazebo/Green</material>
  </gazebo>
  <transmission name="t_box_cilinder_joint3">
    <type>transmission_interface/SimpleTransmission</type>
    <joint name="box_cilinder_joint3">
      <hardwareInterface>EffortJointInterface</hardwareInterface>
    </joint>
    <actuator name="m_box_cilinder_joint3">
      <hardwareInterface>EffortJointInterface</hardwareInterface>
      <mechanicalReduction>1</mechanicalReduction>
    </actuator>
  </transmission>
  <joint name="blue_box3" type="fixed">
    <origin rpy="0 0 0" xyz="0.05 0 0"/>
    <parent link="blue_box3"/>
    <child link="base_link4"/>
  </joint>
  <link name="base_link4">
    <inertial>
      <origin rpy="0 0 0" xyz="0.08 0 -0.0015809"/>
      <mass value="0.2"/>
      <inertia ixx="0.033333" ixy="7.6472E-21" ixz="-1.039E-21" iyy="0.017333" iyz="2.322E-21" izz="0.017333"/>
    </inertial>
    <visual>
      <origin rpy="0 0 0" xyz="0 0 0"/>
      <geometry>
        <mesh filename="package://serpiente_description/urdf/meshes_serpiente/base_link.stl"/>
        <!-- <mesh filename="file:///home/kaiser/catkin_ws_CromaBueno/src/croma_description/meshes/base_link.stl" /> -->
      </geometry>
      <material name="">
        <color rgba="0.79216 0 0.93333 1"/>
      </material>
    </visual>
    <collision>
      <origin rpy="0 0 0" xyz="0 0 0"/>
      <geometry>
        <mesh filename="package://serpiente_description/urdf/meshes_serpiente/base_link.stl"/>
      </geometry>
    </collision>
  </link>
  <link name="cilinder4">
    <inertial>
      <origin rpy="0 0 0" xyz="0.12 2.7756E-17 1.3293E-50"/>
      <mass value="0.7854"/>
      <inertia ixx="0.011454" ixy="2.2588E-20" ixz="3.7494E-36" iyy="0.0098175" iyz="3.7944E-36" izz="0.011454"/>
    </inertial>
    <visual>
      <origin rpy="0 0 0" xyz="0 0 0"/>
      <geometry>
        <mesh filename="package://serpiente_description/urdf/meshes_serpiente/cilinder.stl"/>
      </geometry>
      <material name="">
        <color rgba="1 0 0 1"/>
      </material>
    </visual>
    <collision>
      <origin rpy="0 0 0" xyz="0 0 0"/>
      <geometry>
        <mesh filename="package://serpiente_description/urdf/meshes_serpiente/cilinder.stl"/>
      </geometry>
    </collision>
  </link>
  <joint name="base_cilinder_joint4" type="fixed">
    <origin rpy="1.57079632679 0 0" xyz="0 0 0"/>
    <parent link="base_link4"/>
    <child link="cilinder4"/>
    <axis xyz="0 0 0"/>
  </joint>
  <link name="blue_box4">
    <inertial>
      <origin rpy="0 0 0" xyz="0.04 0 2.0668E-19"/>
      <mass value="0.2"/>
      <inertia ixx="0.033333" ixy="3.4121E-21" ixz="-1.3214E-21" iyy="0.017333" iyz="2.322E-21" izz="0.017333"/>
    </inertial>
    <visual>
      <origin rpy="0 0 0" xyz="0 0 0"/>
      <geometry>
        <mesh filename="package://serpiente_description/urdf/meshes_serpiente/blue_box.stl"/>
      </geometry>
      <material name="">
        <color rgba="0 0 1 1"/>
      </material>
    </visual>
    <collision>
      <origin rpy="0 0 0" xyz="0 0 0"/>
      <geometry>
        <mesh filename="package://serpiente_description/urdf/meshes_serpiente/blue_box.stl"/>
      </geometry>
    </collision>
  </link>
  <joint name="box_cilinder_joint4" type="revolute">
    <origin rpy="0 0 0" xyz="0.05 0 0"/>
    <parent link="cilinder4"/>
    <child link="blue_box4"/>
    <axis xyz="0 1 0"/>
    <limit effort="100" lower="-2.5" upper="2.5" velocity="1000"/>
  </joint>
  <gazebo reference="base_link4">
    <material>Gazebo/Green</material>
  </gazebo>
  <gazebo reference="cilinder4">
    <material>Gazebo/Green</material>
  </gazebo>
  <gazebo reference="blue_box4">
    <material>Gazebo/Green</material>
  </gazebo>
  <transmission name="t_box_cilinder_joint4">
    <type>transmission_interface/SimpleTransmission</type>
    <joint name="box_cilinder_joint4">
      <hardwareInterface>EffortJointInterface</hardwareInterface>
    </joint>
    <actuator name="m_box_cilinder_joint4">
      <hardwareInterface>EffortJointInterface</hardwareInterface>
      <mechanicalReduction>1</mechanicalReduction>
    </actuator>
  </transmission>
  <joint name="blue_box4" type="fixed">
    <origin rpy="0 0 0" xyz="0.05 0 0"/>
    <parent link="blue_box4"/>
    <child link="base_link5"/>
  </joint>
  <link name="base_link5">
    <inertial>
      <origin rpy="0 0 0" xyz="0.08 0 -0.0015809"/>
      <mass value="0.2"/>
      <inertia ixx="0.033333" ixy="7.6472E-21" ixz="-1.039E-21" iyy="0.017333" iyz="2.322E-21" izz="0.017333"/>
    </inertial>
    <visual>
      <origin rpy="0 0 0" xyz="0 0 0"/>
      <geometry>
        <mesh filename="package://serpiente_description/urdf/meshes_serpiente/base_link.stl"/>
        <!-- <mesh filename="file:///home/kaiser/catkin_ws_CromaBueno/src/croma_description/meshes/base_link.stl" /> -->
      </geometry>
      <material name="">
        <color rgba="0.79216 0 0.93333 1"/>
      </material>
    </visual>
    <collision>
      <origin rpy="0 0 0" xyz="0 0 0"/>
      <geometry>
        <mesh filename="package://serpiente_description/urdf/meshes_serpiente/base_link.stl"/>
      </geometry>
    </collision>
  </link>
  <link name="cilinder5">
    <inertial>
      <origin rpy="0 0 0" xyz="0.12 2.7756E-17 1.3293E-50"/>
      <mass value="0.7854"/>
      <inertia ixx="0.011454" ixy="2.2588E-20" ixz="3.7494E-36" iyy="0.0098175" iyz="3.7944E-36" izz="0.011454"/>
    </inertial>
    <visual>
      <origin rpy="0 0 0" xyz="0 0 0"/>
      <geometry>
        <mesh filename="package://serpiente_description/urdf/meshes_serpiente/cilinder.stl"/>
      </geometry>
      <material name="">
        <color rgba="1 0 0 1"/>
      </material>
    </visual>
    <collision>
      <origin rpy="0 0 0" xyz="0 0 0"/>
      <geometry>
        <mesh filename="package://serpiente_description/urdf/meshes_serpiente/cilinder.stl"/>
      </geometry>
    </collision>
  </link>
  <joint name="base_cilinder_joint5" type="fixed">
    <origin rpy="-1.57079632679 0 0" xyz="0 0 0"/>
    <parent link="base_link5"/>
    <child link="cilinder5"/>
    <axis xyz="0 0 0"/>
  </joint>
  <link name="blue_box5">
    <inertial>
      <origin rpy="0 0 0" xyz="0.04 0 2.0668E-19"/>
      <mass value="0.2"/>
      <inertia ixx="0.033333" ixy="3.4121E-21" ixz="-1.3214E-21" iyy="0.017333" iyz="2.322E-21" izz="0.017333"/>
    </inertial>
    <visual>
      <origin rpy="0 0 0" xyz="0 0 0"/>
      <geometry>
        <mesh filename="package://serpiente_description/urdf/meshes_serpiente/blue_box.stl"/>
      </geometry>
      <material name="">
        <color rgba="0 0 1 1"/>
      </material>
    </visual>
    <collision>
      <origin rpy="0 0 0" xyz="0 0 0"/>
      <geometry>
        <mesh filename="package://serpiente_description/urdf/meshes_serpiente/blue_box.stl"/>
      </geometry>
    </collision>
  </link>
  <joint name="box_cilinder_joint5" type="revolute">
    <origin rpy="0 0 0" xyz="0.05 0 0"/>
    <parent link="cilinder5"/>
    <child link="blue_box5"/>
    <axis xyz="0 1 0"/>
    <limit effort="100" lower="-2.5" upper="2.5" velocity="1000"/>
  </joint>
  <gazebo reference="base_link5">
    <material>Gazebo/Green</material>
  </gazebo>
  <gazebo reference="cilinder5">
    <material>Gazebo/Green</material>
  </gazebo>
  <gazebo reference="blue_box5">
    <material>Gazebo/Green</material>
  </gazebo>
  <transmission name="t_box_cilinder_joint5">
    <type>transmission_interface/SimpleTransmission</type>
    <joint name="box_cilinder_joint5">
      <hardwareInterface>EffortJointInterface</hardwareInterface>
    </joint>
    <actuator name="m_box_cilinder_joint5">
      <hardwareInterface>EffortJointInterface</hardwareInterface>
      <mechanicalReduction>1</mechanicalReduction>
    </actuator>
  </transmission>
  <joint name="blue_box5" type="fixed">
    <origin rpy="0 0 0" xyz="0.05 0 0"/>
    <parent link="blue_box5"/>
    <child link="base_link6"/>
  </joint>
  <link name="base_link6">
    <inertial>
      <origin rpy="0 0 0" xyz="0.08 0 -0.0015809"/>
      <mass value="0.2"/>
      <inertia ixx="0.033333" ixy="7.6472E-21" ixz="-1.039E-21" iyy="0.017333" iyz="2.322E-21" izz="0.017333"/>
    </inertial>
    <visual>
      <origin rpy="0 0 0" xyz="0 0 0"/>
      <geometry>
        <mesh filename="package://serpiente_description/urdf/meshes_serpiente/base_link.stl"/>
        <!-- <mesh filename="file:///home/kaiser/catkin_ws_CromaBueno/src/croma_description/meshes/base_link.stl" /> -->
      </geometry>
      <material name="">
        <color rgba="0.79216 0 0.93333 1"/>
      </material>
    </visual>
    <collision>
      <origin rpy="0 0 0" xyz="0 0 0"/>
      <geometry>
        <mesh filename="package://serpiente_description/urdf/meshes_serpiente/base_link.stl"/>
      </geometry>
    </collision>
  </link>
  <link name="cilinder6">
    <inertial>
      <origin rpy="0 0 0" xyz="0.12 2.7756E-17 1.3293E-50"/>
      <mass value="0.7854"/>
      <inertia ixx="0.011454" ixy="2.2588E-20" ixz="3.7494E-36" iyy="0.0098175" iyz="3.7944E-36" izz="0.011454"/>
    </inertial>
    <visual>
      <origin rpy="0 0 0" xyz="0 0 0"/>
      <geometry>
        <mesh filename="package://serpiente_description/urdf/meshes_serpiente/cilinder.stl"/>
      </geometry>
      <material name="">
        <color rgba="1 0 0 1"/>
      </material>
    </visual>
    <collision>
      <origin rpy="0 0 0" xyz="0 0 0"/>
      <geometry>
        <mesh filename="package://serpiente_description/urdf/meshes_serpiente/cilinder.stl"/>
      </geometry>
    </collision>
  </link>
  <joint name="base_cilinder_joint6" type="fixed">
    <origin rpy="1.57079632679 0 0" xyz="0 0 0"/>
    <parent link="base_link6"/>
    <child link="cilinder6"/>
    <axis xyz="0 0 0"/>
  </joint>
  <link name="blue_box6">
    <inertial>
      <origin rpy="0 0 0" xyz="0.04 0 2.0668E-19"/>
      <mass value="0.2"/>
      <inertia ixx="0.033333" ixy="3.4121E-21" ixz="-1.3214E-21" iyy="0.017333" iyz="2.322E-21" izz="0.017333"/>
    </inertial>
    <visual>
      <origin rpy="0 0 0" xyz="0 0 0"/>
      <geometry>
        <mesh filename="package://serpiente_description/urdf/meshes_serpiente/blue_box.stl"/>
      </geometry>
      <material name="">
        <color rgba="0 0 1 1"/>
      </material>
    </visual>
    <collision>
      <origin rpy="0 0 0" xyz="0 0 0"/>
      <geometry>
        <mesh filename="package://serpiente_description/urdf/meshes_serpiente/blue_box.stl"/>
      </geometry>
    </collision>
  </link>
  <joint name="box_cilinder_joint6" type="revolute">
    <origin rpy="0 0 0" xyz="0.05 0 0"/>
    <parent link="cilinder6"/>
    <child link="blue_box6"/>
    <axis xyz="0 1 0"/>
    <limit effort="100" lower="-2.5" upper="2.5" velocity="1000"/>
  </joint>
  <gazebo reference="base_link6">
    <material>Gazebo/Green</material>
  </gazebo>
  <gazebo reference="cilinder6">
    <material>Gazebo/Green</material>
  </gazebo>
  <gazebo reference="blue_box6">
    <material>Gazebo/Green</material>
  </gazebo>
  <transmission name="t_box_cilinder_joint6">
    <type>transmission_interface/SimpleTransmission</type>
    <joint name="box_cilinder_joint6">
      <hardwareInterface>EffortJointInterface</hardwareInterface>
    </joint>
    <actuator name="m_box_cilinder_joint6">
      <hardwareInterface>EffortJointInterface</hardwareInterface>
      <mechanicalReduction>1</mechanicalReduction>
    </actuator>
  </transmission>
  <joint name="blue_box6" type="fixed">
    <origin rpy="0 0 0" xyz="0.05 0 0"/>
    <parent link="blue_box6"/>
    <child link="base_link7"/>
  </joint>
  <link name="base_link7">
    <inertial>
      <origin rpy="0 0 0" xyz="0.08 0 -0.0015809"/>
      <mass value="0.2"/>
      <inertia ixx="0.033333" ixy="7.6472E-21" ixz="-1.039E-21" iyy="0.017333" iyz="2.322E-21" izz="0.017333"/>
    </inertial>
    <visual>
      <origin rpy="0 0 0" xyz="0 0 0"/>
      <geometry>
        <mesh filename="package://serpiente_description/urdf/meshes_serpiente/base_link.stl"/>
        <!-- <mesh filename="file:///home/kaiser/catkin_ws_CromaBueno/src/croma_description/meshes/base_link.stl" /> -->
      </geometry>
      <material name="">
        <color rgba="0.79216 0 0.93333 1"/>
      </material>
    </visual>
    <collision>
      <origin rpy="0 0 0" xyz="0 0 0"/>
      <geometry>
        <mesh filename="package://serpiente_description/urdf/meshes_serpiente/base_link.stl"/>
      </geometry>
    </collision>
  </link>
  <link name="cilinder7">
    <inertial>
      <origin rpy="0 0 0" xyz="0.12 2.7756E-17 1.3293E-50"/>
      <mass value="0.7854"/>
      <inertia ixx="0.011454" ixy="2.2588E-20" ixz="3.7494E-36" iyy="0.0098175" iyz="3.7944E-36" izz="0.011454"/>
    </inertial>
    <visual>
      <origin rpy="0 0 0" xyz="0 0 0"/>
      <geometry>
        <mesh filename="package://serpiente_description/urdf/meshes_serpiente/cilinder.stl"/>
      </geometry>
      <material name="">
        <color rgba="1 0 0 1"/>
      </material>
    </visual>
    <collision>
      <origin rpy="0 0 0" xyz="0 0 0"/>
      <geometry>
        <mesh filename="package://serpiente_description/urdf/meshes_serpiente/cilinder.stl"/>
      </geometry>
    </collision>
  </link>
  <joint name="base_cilinder_joint7" type="fixed">
    <origin rpy="-1.57079632679 0 0" xyz="0 0 0"/>
    <parent link="base_link7"/>
    <child link="cilinder7"/>
    <axis xyz="0 0 0"/>
  </joint>
  <link name="blue_box7">
    <inertial>
      <origin rpy="0 0 0" xyz="0.04 0 2.0668E-19"/>
      <mass value="0.2"/>
      <inertia ixx="0.033333" ixy="3.4121E-21" ixz="-1.3214E-21" iyy="0.017333" iyz="2.322E-21" izz="0.017333"/>
    </inertial>
    <visual>
      <origin rpy="0 0 0" xyz="0 0 0"/>
      <geometry>
        <mesh filename="package://serpiente_description/urdf/meshes_serpiente/blue_box.stl"/>
      </geometry>
      <material name="">
        <color rgba="0 0 1 1"/>
      </material>
    </visual>
    <collision>
      <origin rpy="0 0 0" xyz="0 0 0"/>
      <geometry>
        <mesh filename="package://serpiente_description/urdf/meshes_serpiente/blue_box.stl"/>
      </geometry>
    </collision>
  </link>
  <joint name="box_cilinder_joint7" type="revolute">
    <origin rpy="0 0 0" xyz="0.05 0 0"/>
    <parent link="cilinder7"/>
    <child link="blue_box7"/>
    <axis xyz="0 1 0"/>
    <limit effort="100" lower="-2.5" upper="2.5" velocity="1000"/>
  </joint>
  <gazebo reference="base_link7">
    <material>Gazebo/Green</material>
  </gazebo>
  <gazebo reference="cilinder7">
    <material>Gazebo/Green</material>
  </gazebo>
  <gazebo reference="blue_box7">
    <material>Gazebo/Green</material>
  </gazebo>
  <transmission name="t_box_cilinder_joint7">
    <type>transmission_interface/SimpleTransmission</type>
    <joint name="box_cilinder_joint7">
      <hardwareInterface>EffortJointInterface</hardwareInterface>
    </joint>
    <actuator name="m_box_cilinder_joint7">
      <hardwareInterface>EffortJointInterface</hardwareInterface>
      <mechanicalReduction>1</mechanicalReduction>
    </actuator>
  </transmission>
  <joint name="blue_box7" type="fixed">
    <origin rpy="0 0 0" xyz="0.05 0 0"/>
    <parent link="blue_box7"/>
    <child link="base_link8"/>
  </joint>
  <link name="base_link8">
    <inertial>
      <origin rpy="0 0 0" xyz="0.08 0 -0.0015809"/>
      <mass value="0.2"/>
      <inertia ixx="0.033333" ixy="7.6472E-21" ixz="-1.039E-21" iyy="0.017333" iyz="2.322E-21" izz="0.017333"/>
    </inertial>
    <visual>
      <origin rpy="0 0 0" xyz="0 0 0"/>
      <geometry>
        <mesh filename="package://serpiente_description/urdf/meshes_serpiente/base_link.stl"/>
        <!-- <mesh filename="file:///home/kaiser/catkin_ws_CromaBueno/src/croma_description/meshes/base_link.stl" /> -->
      </geometry>
      <material name="">
        <color rgba="0.79216 0 0.93333 1"/>
      </material>
    </visual>
    <collision>
      <origin rpy="0 0 0" xyz="0 0 0"/>
      <geometry>
        <mesh filename="package://serpiente_description/urdf/meshes_serpiente/base_link.stl"/>
      </geometry>
    </collision>
  </link>
  <link name="cilinder8">
    <inertial>
      <origin rpy="0 0 0" xyz="0.12 2.7756E-17 1.3293E-50"/>
      <mass value="0.7854"/>
      <inertia ixx="0.011454" ixy="2.2588E-20" ixz="3.7494E-36" iyy="0.0098175" iyz="3.7944E-36" izz="0.011454"/>
    </inertial>
    <visual>
      <origin rpy="0 0 0" xyz="0 0 0"/>
      <geometry>
        <mesh filename="package://serpiente_description/urdf/meshes_serpiente/cilinder.stl"/>
      </geometry>
      <material name="">
        <color rgba="1 0 0 1"/>
      </material>
    </visual>
    <collision>
      <origin rpy="0 0 0" xyz="0 0 0"/>
      <geometry>
        <mesh filename="package://serpiente_description/urdf/meshes_serpiente/cilinder.stl"/>
      </geometry>
    </collision>
  </link>
  <joint name="base_cilinder_joint8" type="fixed">
    <origin rpy="1.57079632679 0 0" xyz="0 0 0"/>
    <parent link="base_link8"/>
    <child link="cilinder8"/>
    <axis xyz="0 0 0"/>
  </joint>
  <link name="blue_box8">
    <inertial>
      <origin rpy="0 0 0" xyz="0.04 0 2.0668E-19"/>
      <mass value="0.2"/>
      <inertia ixx="0.033333" ixy="3.4121E-21" ixz="-1.3214E-21" iyy="0.017333" iyz="2.322E-21" izz="0.017333"/>
    </inertial>
    <visual>
      <origin rpy="0 0 0" xyz="0 0 0"/>
      <geometry>
        <mesh filename="package://serpiente_description/urdf/meshes_serpiente/blue_box.stl"/>
      </geometry>
      <material name="">
        <color rgba="0 0 1 1"/>
      </material>
    </visual>
    <collision>
      <origin rpy="0 0 0" xyz="0 0 0"/>
      <geometry>
        <mesh filename="package://serpiente_description/urdf/meshes_serpiente/blue_box.stl"/>
      </geometry>
    </collision>
  </link>
  <joint name="box_cilinder_joint8" type="revolute">
    <origin rpy="0 0 0" xyz="0.05 0 0"/>
    <parent link="cilinder8"/>
    <child link="blue_box8"/>
    <axis xyz="0 1 0"/>
    <limit effort="100" lower="-2.5" upper="2.5" velocity="1000"/>
  </joint>
  <gazebo reference="base_link8">
    <material>Gazebo/Green</material>
  </gazebo>
  <gazebo reference="cilinder8">
    <material>Gazebo/Green</material>
  </gazebo>
  <gazebo reference="blue_box8">
    <material>Gazebo/Green</material>
  </gazebo>
  <transmission name="t_box_cilinder_joint8">
    <type>transmission_interface/SimpleTransmission</type>
    <joint name="box_cilinder_joint8">
      <hardwareInterface>EffortJointInterface</hardwareInterface>
    </joint>
    <actuator name="m_box_cilinder_joint8">
      <hardwareInterface>EffortJointInterface</hardwareInterface>
      <mechanicalReduction>1</mechanicalReduction>
    </actuator>
  </transmission>
  <joint name="blue_box8" type="fixed">
    <origin rpy="0 0 0" xyz="0.05 0 0"/>
    <parent link="blue_box8"/>
    <child link="base_link9"/>
  </joint>
  <link name="base_link9">
    <inertial>
      <origin rpy="0 0 0" xyz="0.08 0 -0.0015809"/>
      <mass value="0.2"/>
      <inertia ixx="0.033333" ixy="7.6472E-21" ixz="-1.039E-21" iyy="0.017333" iyz="2.322E-21" izz="0.017333"/>
    </inertial>
    <visual>
      <origin rpy="0 0 0" xyz="0 0 0"/>
      <geometry>
        <mesh filename="package://serpiente_description/urdf/meshes_serpiente/base_link.stl"/>
        <!-- <mesh filename="file:///home/kaiser/catkin_ws_CromaBueno/src/croma_description/meshes/base_link.stl" /> -->
      </geometry>
      <material name="">
        <color rgba="0.79216 0 0.93333 1"/>
      </material>
    </visual>
    <collision>
      <origin rpy="0 0 0" xyz="0 0 0"/>
      <geometry>
        <mesh filename="package://serpiente_description/urdf/meshes_serpiente/base_link.stl"/>
      </geometry>
    </collision>
  </link>
  <link name="cilinder9">
    <inertial>
      <origin rpy="0 0 0" xyz="0.12 2.7756E-17 1.3293E-50"/>
      <mass value="0.7854"/>
      <inertia ixx="0.011454" ixy="2.2588E-20" ixz="3.7494E-36" iyy="0.0098175" iyz="3.7944E-36" izz="0.011454"/>
    </inertial>
    <visual>
      <origin rpy="0 0 0" xyz="0 0 0"/>
      <geometry>
        <mesh filename="package://serpiente_description/urdf/meshes_serpiente/cilinder.stl"/>
      </geometry>
      <material name="">
        <color rgba="1 0 0 1"/>
      </material>
    </visual>
    <collision>
      <origin rpy="0 0 0" xyz="0 0 0"/>
      <geometry>
        <mesh filename="package://serpiente_description/urdf/meshes_serpiente/cilinder.stl"/>
      </geometry>
    </collision>
  </link>
  <joint name="base_cilinder_joint9" type="fixed">
    <origin rpy="-1.57079632679 0 0" xyz="0 0 0"/>
    <parent link="base_link9"/>
    <child link="cilinder9"/>
    <axis xyz="0 0 0"/>
  </joint>
  <link name="blue_box9">
    <inertial>
      <origin rpy="0 0 0" xyz="0.04 0 2.0668E-19"/>
      <mass value="0.2"/>
      <inertia ixx="0.033333" ixy="3.4121E-21" ixz="-1.3214E-21" iyy="0.017333" iyz="2.322E-21" izz="0.017333"/>
    </inertial>
    <visual>
      <origin rpy="0 0 0" xyz="0 0 0"/>
      <geometry>
        <mesh filename="package://serpiente_description/urdf/meshes_serpiente/blue_box.stl"/>
      </geometry>
      <material name="">
        <color rgba="0 0 1 1"/>
      </material>
    </visual>
    <collision>
      <origin rpy="0 0 0" xyz="0 0 0"/>
      <geometry>
        <mesh filename="package://serpiente_description/urdf/meshes_serpiente/blue_box.stl"/>
      </geometry>
    </collision>
  </link>
  <joint name="box_cilinder_joint9" type="revolute">
    <origin rpy="0 0 0" xyz="0.05 0 0"/>
    <parent link="cilinder9"/>
    <child link="blue_box9"/>
    <axis xyz="0 1 0"/>
    <limit effort="100" lower="-2.5" upper="2.5" velocity="1000"/>
  </joint>
  <gazebo reference="base_link9">
    <material>Gazebo/Green</material>
  </gazebo>
  <gazebo reference="cilinder9">
    <material>Gazebo/Green</material>
  </gazebo>
  <gazebo reference="blue_box9">
    <material>Gazebo/Green</material>
  </gazebo>
  <transmission name="t_box_cilinder_joint9">
    <type>transmission_interface/SimpleTransmission</type>
    <joint name="box_cilinder_joint9">
      <hardwareInterface>EffortJointInterface</hardwareInterface>
    </joint>
    <actuator name="m_box_cilinder_joint9">
      <hardwareInterface>EffortJointInterface</hardwareInterface>
      <mechanicalReduction>1</mechanicalReduction>
    </actuator>
  </transmission>
</robot>
