<?xml version="1.0" ?>
<!-- =================================================================================== -->
<!-- |    This document was autogenerated by xacro from /home/kaiser/WS_ROS/ws_tfg/src/hexapodo/hexapodo_description/urdf/mi_hexapodo_3dof.xacro | -->
<!-- |    EDITING THIS FILE BY HAND IS NOT RECOMMENDED                                 | -->
<!-- =================================================================================== -->
<robot name="hexapodo" xmlns:xacro="http://ros.org/wiki/xacro">
  <!-- Propiedades articulaciones -->
  <!-- Chasis -->
  <link name="map"/>
  <joint name="base_joint" type="fixed">
    <parent link="map"/>
    <child link="base_link"/>
    <origin rpy="0 0 0" xyz="0 0 0"/>
  </joint>
  <link name="base_link">
    <inertial>
      <origin rpy="0 0 0" xyz="0 0 0"/>
      <mass value="0.5"/>
      <inertia ixx="0.569270833333" ixy="0" ixz="0" iyy="2.63648666667" iyz="0" izz="2.63648666667"/>
    </inertial>
    <visual>
      <origin rpy="0 0 0" xyz="0 0 0"/>
      <geometry>
        <box size="0.42672 0.165 0.01"/>
      </geometry>
      <material name="">
        <color rgba="0.7 0.7 0.7 1"/>
      </material>
    </visual>
    <collision>
      <origin rpy="0 0 0" xyz="0 0 0"/>
      <geometry>
        <box size="0.3556 0.165 0.004"/>
      </geometry>
    </collision>
  </link>
  <!-- Leg macro -->
  <!-- Modelo del robot -->
  <!-- leg position -->
  <joint name="leg_center_joint_RR" type="fixed">
    <origin rpy="0 0 0" xyz="0.1778 -0.08335 0"/>
    <parent link="base_link"/>
    <child link="leg_center_RR"/>
  </joint>
  <link name="leg_center_RR">
    <inertial>
      <origin rpy="0 0 0" xyz="0 0 0"/>
      <mass value="0.5"/>
      <inertia ixx="0.569270833333" ixy="0" ixz="0" iyy="2.63648666667" iyz="0" izz="2.63648666667"/>
    </inertial>
  </link>
  <!-- coxa -->
  <joint name="coxa_joint_RR" type="revolute">
    <origin rpy="0 0 -1.57079632679" xyz="0 0 0"/>
    <parent link="leg_center_RR"/>
    <child link="coxa_RR"/>
    <axis xyz="0 0 1"/>
    <limit effort="10000" lower="-3.14" upper="3.14" velocity="100"/>
  </joint>
  <link name="coxa_RR">
    <inertial>
      <origin rpy="0 0 0" xyz="0 0 0"/>
      <mass value="0.15"/>
      <inertia ixx="0.0096265625" ixy="0" ixz="0" iyy="0.093420185" iyz="0" izz="0.093420185"/>
    </inertial>
    <visual>
      <origin rpy="0 0 0" xyz="0.029465 0 0"/>
      <geometry>
        <box size="0.05893 0.022 0.0325"/>
      </geometry>
      <material name="">
        <color rgba="0.7 0.7 0.7 1"/>
      </material>
    </visual>
    <collision>
      <origin rpy="0 0 0" xyz="0.029465 0 0"/>
      <geometry>
        <box size="0.05893 0.022 0.0325"/>
      </geometry>
    </collision>
  </link>
  <!-- femur -->
  <joint name="femur_joint_RR" type="revolute">
    <origin rpy="-1.57079632679 +0.63 0" xyz="0.05893 0 0"/>
    <parent link="coxa_RR"/>
    <child link="femur_RR"/>
    <axis xyz="0 0 1"/>
    <limit effort="10000" lower="-3.14" upper="3.14" velocity="100"/>
  </joint>
  <link name="femur_RR">
    <inertial>
      <origin rpy="0 0 0" xyz="0 -0.05399 0"/>
      <mass value="0.15"/>
      <inertia ixx="0.079474565" ixy="0" ixz="0" iyy="0.0096265625" iyz="0" izz="0.0096265625"/>
    </inertial>
    <visual>
      <origin rpy="0 0 0" xyz="0 -0.05399 0"/>
      <geometry>
        <box size="0.022 0.10798 0.0325"/>
      </geometry>
      <material name="">
        <color rgba="0.7 0.7 0.7 1"/>
      </material>
    </visual>
    <collision>
      <origin rpy="0 0 0" xyz="0 -0.05399 0"/>
      <geometry>
        <box size="0.022 0.10798 0.0325"/>
      </geometry>
    </collision>
  </link>
  <!-- tibia -->
  <joint name="tibia_joint_RR" type="revolute">
    <origin rpy="3.14159265359 0 0.63" xyz="0 -0.10798 0"/>
    <parent link="femur_RR"/>
    <child link="tibia_RR"/>
    <axis xyz="0 0 1"/>
    <limit effort="10000" lower="-3.14" upper="3.14" velocity="100"/>
  </joint>
  <link name="tibia_RR">
    <inertial>
      <origin rpy="0 0 0" xyz="0.1 0 0"/>
      <mass value="0.15"/>
      <inertia ixx="0.0096265625" ixy="0" ixz="0" iyy="0.2566015625" iyz="0" izz="0.2566015625"/>
    </inertial>
    <visual>
      <origin rpy="0 0 0" xyz="0.1 0 0"/>
      <geometry>
        <box size="0.2 0.022 0.0325"/>
      </geometry>
      <material name="">
        <color rgba="0.7 0.7 0.7 1"/>
      </material>
    </visual>
    <visual>
      <origin rpy="0 0 0" xyz="0.2 0 0"/>
      <geometry>
        <sphere radius="0.015"/>
      </geometry>
      <material name="">
        <color rgba="0.7 0.7 0.7 1"/>
      </material>
    </visual>
    <collision>
      <origin rpy="0 0 0" xyz="0.1 0 0"/>
      <geometry>
        <box size="0.2 0.022 0.0325"/>
      </geometry>
      <collision>
        <origin rpy="0 0 0" xyz="0.2 0 0"/>
        <geometry>
          <sphere radius="0.015"/>
        </geometry>
      </collision>
    </collision>
  </link>
  <!-- leg position -->
  <joint name="leg_center_joint_RM" type="fixed">
    <origin rpy="0 0 0" xyz="0.0 -0.08335 0"/>
    <parent link="base_link"/>
    <child link="leg_center_RM"/>
  </joint>
  <link name="leg_center_RM">
    <inertial>
      <origin rpy="0 0 0" xyz="0 0 0"/>
      <mass value="0.5"/>
      <inertia ixx="0.569270833333" ixy="0" ixz="0" iyy="2.63648666667" iyz="0" izz="2.63648666667"/>
    </inertial>
  </link>
  <!-- coxa -->
  <joint name="coxa_joint_RM" type="revolute">
    <origin rpy="0 0 -1.57079632679" xyz="0 0 0"/>
    <parent link="leg_center_RM"/>
    <child link="coxa_RM"/>
    <axis xyz="0 0 1"/>
    <limit effort="10000" lower="-3.14" upper="3.14" velocity="100"/>
  </joint>
  <link name="coxa_RM">
    <inertial>
      <origin rpy="0 0 0" xyz="0 0 0"/>
      <mass value="0.15"/>
      <inertia ixx="0.0096265625" ixy="0" ixz="0" iyy="0.093420185" iyz="0" izz="0.093420185"/>
    </inertial>
    <visual>
      <origin rpy="0 0 0" xyz="0.029465 0 0"/>
      <geometry>
        <box size="0.05893 0.022 0.0325"/>
      </geometry>
      <material name="">
        <color rgba="0.7 0.7 0.7 1"/>
      </material>
    </visual>
    <collision>
      <origin rpy="0 0 0" xyz="0.029465 0 0"/>
      <geometry>
        <box size="0.05893 0.022 0.0325"/>
      </geometry>
    </collision>
  </link>
  <!-- femur -->
  <joint name="femur_joint_RM" type="revolute">
    <origin rpy="-1.57079632679 +0.63 0" xyz="0.05893 0 0"/>
    <parent link="coxa_RM"/>
    <child link="femur_RM"/>
    <axis xyz="0 0 1"/>
    <limit effort="10000" lower="-3.14" upper="3.14" velocity="100"/>
  </joint>
  <link name="femur_RM">
    <inertial>
      <origin rpy="0 0 0" xyz="0 -0.05399 0"/>
      <mass value="0.15"/>
      <inertia ixx="0.079474565" ixy="0" ixz="0" iyy="0.0096265625" iyz="0" izz="0.0096265625"/>
    </inertial>
    <visual>
      <origin rpy="0 0 0" xyz="0 -0.05399 0"/>
      <geometry>
        <box size="0.022 0.10798 0.0325"/>
      </geometry>
      <material name="">
        <color rgba="0.7 0.7 0.7 1"/>
      </material>
    </visual>
    <collision>
      <origin rpy="0 0 0" xyz="0 -0.05399 0"/>
      <geometry>
        <box size="0.022 0.10798 0.0325"/>
      </geometry>
    </collision>
  </link>
  <!-- tibia -->
  <joint name="tibia_joint_RM" type="revolute">
    <origin rpy="3.14159265359 0 0.63" xyz="0 -0.10798 0"/>
    <parent link="femur_RM"/>
    <child link="tibia_RM"/>
    <axis xyz="0 0 1"/>
    <limit effort="10000" lower="-3.14" upper="3.14" velocity="100"/>
  </joint>
  <link name="tibia_RM">
    <inertial>
      <origin rpy="0 0 0" xyz="0.1 0 0"/>
      <mass value="0.15"/>
      <inertia ixx="0.0096265625" ixy="0" ixz="0" iyy="0.2566015625" iyz="0" izz="0.2566015625"/>
    </inertial>
    <visual>
      <origin rpy="0 0 0" xyz="0.1 0 0"/>
      <geometry>
        <box size="0.2 0.022 0.0325"/>
      </geometry>
      <material name="">
        <color rgba="0.7 0.7 0.7 1"/>
      </material>
    </visual>
    <visual>
      <origin rpy="0 0 0" xyz="0.2 0 0"/>
      <geometry>
        <sphere radius="0.015"/>
      </geometry>
      <material name="">
        <color rgba="0.7 0.7 0.7 1"/>
      </material>
    </visual>
    <collision>
      <origin rpy="0 0 0" xyz="0.1 0 0"/>
      <geometry>
        <box size="0.2 0.022 0.0325"/>
      </geometry>
      <collision>
        <origin rpy="0 0 0" xyz="0.2 0 0"/>
        <geometry>
          <sphere radius="0.015"/>
        </geometry>
      </collision>
    </collision>
  </link>
  <!-- leg position -->
  <joint name="leg_center_joint_RF" type="fixed">
    <origin rpy="0 0 0" xyz="-0.1778 -0.08335 0"/>
    <parent link="base_link"/>
    <child link="leg_center_RF"/>
  </joint>
  <link name="leg_center_RF">
    <inertial>
      <origin rpy="0 0 0" xyz="0 0 0"/>
      <mass value="0.5"/>
      <inertia ixx="0.569270833333" ixy="0" ixz="0" iyy="2.63648666667" iyz="0" izz="2.63648666667"/>
    </inertial>
  </link>
  <!-- coxa -->
  <joint name="coxa_joint_RF" type="revolute">
    <origin rpy="0 0 -1.57079632679" xyz="0 0 0"/>
    <parent link="leg_center_RF"/>
    <child link="coxa_RF"/>
    <axis xyz="0 0 1"/>
    <limit effort="10000" lower="-3.14" upper="3.14" velocity="100"/>
  </joint>
  <link name="coxa_RF">
    <inertial>
      <origin rpy="0 0 0" xyz="0 0 0"/>
      <mass value="0.15"/>
      <inertia ixx="0.0096265625" ixy="0" ixz="0" iyy="0.093420185" iyz="0" izz="0.093420185"/>
    </inertial>
    <visual>
      <origin rpy="0 0 0" xyz="0.029465 0 0"/>
      <geometry>
        <box size="0.05893 0.022 0.0325"/>
      </geometry>
      <material name="">
        <color rgba="0.7 0.7 0.7 1"/>
      </material>
    </visual>
    <collision>
      <origin rpy="0 0 0" xyz="0.029465 0 0"/>
      <geometry>
        <box size="0.05893 0.022 0.0325"/>
      </geometry>
    </collision>
  </link>
  <!-- femur -->
  <joint name="femur_joint_RF" type="revolute">
    <origin rpy="-1.57079632679 +0.63 0" xyz="0.05893 0 0"/>
    <parent link="coxa_RF"/>
    <child link="femur_RF"/>
    <axis xyz="0 0 1"/>
    <limit effort="10000" lower="-3.14" upper="3.14" velocity="100"/>
  </joint>
  <link name="femur_RF">
    <inertial>
      <origin rpy="0 0 0" xyz="0 -0.05399 0"/>
      <mass value="0.15"/>
      <inertia ixx="0.079474565" ixy="0" ixz="0" iyy="0.0096265625" iyz="0" izz="0.0096265625"/>
    </inertial>
    <visual>
      <origin rpy="0 0 0" xyz="0 -0.05399 0"/>
      <geometry>
        <box size="0.022 0.10798 0.0325"/>
      </geometry>
      <material name="">
        <color rgba="0.7 0.7 0.7 1"/>
      </material>
    </visual>
    <collision>
      <origin rpy="0 0 0" xyz="0 -0.05399 0"/>
      <geometry>
        <box size="0.022 0.10798 0.0325"/>
      </geometry>
    </collision>
  </link>
  <!-- tibia -->
  <joint name="tibia_joint_RF" type="revolute">
    <origin rpy="3.14159265359 0 0.63" xyz="0 -0.10798 0"/>
    <parent link="femur_RF"/>
    <child link="tibia_RF"/>
    <axis xyz="0 0 1"/>
    <limit effort="10000" lower="-3.14" upper="3.14" velocity="100"/>
  </joint>
  <link name="tibia_RF">
    <inertial>
      <origin rpy="0 0 0" xyz="0.1 0 0"/>
      <mass value="0.15"/>
      <inertia ixx="0.0096265625" ixy="0" ixz="0" iyy="0.2566015625" iyz="0" izz="0.2566015625"/>
    </inertial>
    <visual>
      <origin rpy="0 0 0" xyz="0.1 0 0"/>
      <geometry>
        <box size="0.2 0.022 0.0325"/>
      </geometry>
      <material name="">
        <color rgba="0.7 0.7 0.7 1"/>
      </material>
    </visual>
    <visual>
      <origin rpy="0 0 0" xyz="0.2 0 0"/>
      <geometry>
        <sphere radius="0.015"/>
      </geometry>
      <material name="">
        <color rgba="0.7 0.7 0.7 1"/>
      </material>
    </visual>
    <collision>
      <origin rpy="0 0 0" xyz="0.1 0 0"/>
      <geometry>
        <box size="0.2 0.022 0.0325"/>
      </geometry>
      <collision>
        <origin rpy="0 0 0" xyz="0.2 0 0"/>
        <geometry>
          <sphere radius="0.015"/>
        </geometry>
      </collision>
    </collision>
  </link>
  <!-- leg position -->
  <joint name="leg_center_joint_LR" type="fixed">
    <origin rpy="0 0 0" xyz="0.1778 0.08335 0"/>
    <parent link="base_link"/>
    <child link="leg_center_LR"/>
  </joint>
  <link name="leg_center_LR">
    <inertial>
      <origin rpy="0 0 0" xyz="0 0 0"/>
      <mass value="0.5"/>
      <inertia ixx="0.569270833333" ixy="0" ixz="0" iyy="2.63648666667" iyz="0" izz="2.63648666667"/>
    </inertial>
  </link>
  <!-- coxa -->
  <joint name="coxa_joint_LR" type="revolute">
    <origin rpy="0 0 1.57079632679" xyz="0 0 0"/>
    <parent link="leg_center_LR"/>
    <child link="coxa_LR"/>
    <axis xyz="0 0 -1"/>
    <limit effort="10000" lower="-3.14" upper="3.14" velocity="100"/>
  </joint>
  <link name="coxa_LR">
    <inertial>
      <origin rpy="0 0 0" xyz="0 0 0"/>
      <mass value="0.15"/>
      <inertia ixx="0.0096265625" ixy="0" ixz="0" iyy="0.093420185" iyz="0" izz="0.093420185"/>
    </inertial>
    <visual>
      <origin rpy="0 0 0" xyz="0.029465 0 0"/>
      <geometry>
        <box size="0.05893 0.022 0.0325"/>
      </geometry>
      <material name="">
        <color rgba="0.7 0.7 0.7 1"/>
      </material>
    </visual>
    <collision>
      <origin rpy="0 0 0" xyz="0.029465 0 0"/>
      <geometry>
        <box size="0.05893 0.022 0.0325"/>
      </geometry>
    </collision>
  </link>
  <!-- femur -->
  <joint name="femur_joint_LR" type="revolute">
    <origin rpy="-1.57079632679 +0.63 0" xyz="0.05893 0 0"/>
    <parent link="coxa_LR"/>
    <child link="femur_LR"/>
    <axis xyz="0 0 -1"/>
    <limit effort="10000" lower="-3.14" upper="3.14" velocity="100"/>
  </joint>
  <link name="femur_LR">
    <inertial>
      <origin rpy="0 0 0" xyz="0 -0.05399 0"/>
      <mass value="0.15"/>
      <inertia ixx="0.079474565" ixy="0" ixz="0" iyy="0.0096265625" iyz="0" izz="0.0096265625"/>
    </inertial>
    <visual>
      <origin rpy="0 0 0" xyz="0 -0.05399 0"/>
      <geometry>
        <box size="0.022 0.10798 0.0325"/>
      </geometry>
      <material name="">
        <color rgba="0.7 0.7 0.7 1"/>
      </material>
    </visual>
    <collision>
      <origin rpy="0 0 0" xyz="0 -0.05399 0"/>
      <geometry>
        <box size="0.022 0.10798 0.0325"/>
      </geometry>
    </collision>
  </link>
  <!-- tibia -->
  <joint name="tibia_joint_LR" type="revolute">
    <origin rpy="3.14159265359 0 0.63" xyz="0 -0.10798 0"/>
    <parent link="femur_LR"/>
    <child link="tibia_LR"/>
    <axis xyz="0 0 -1"/>
    <limit effort="10000" lower="-3.14" upper="3.14" velocity="100"/>
  </joint>
  <link name="tibia_LR">
    <inertial>
      <origin rpy="0 0 0" xyz="0.1 0 0"/>
      <mass value="0.15"/>
      <inertia ixx="0.0096265625" ixy="0" ixz="0" iyy="0.2566015625" iyz="0" izz="0.2566015625"/>
    </inertial>
    <visual>
      <origin rpy="0 0 0" xyz="0.1 0 0"/>
      <geometry>
        <box size="0.2 0.022 0.0325"/>
      </geometry>
      <material name="">
        <color rgba="0.7 0.7 0.7 1"/>
      </material>
    </visual>
    <visual>
      <origin rpy="0 0 0" xyz="0.2 0 0"/>
      <geometry>
        <sphere radius="0.015"/>
      </geometry>
      <material name="">
        <color rgba="0.7 0.7 0.7 1"/>
      </material>
    </visual>
    <collision>
      <origin rpy="0 0 0" xyz="0.1 0 0"/>
      <geometry>
        <box size="0.2 0.022 0.0325"/>
      </geometry>
      <collision>
        <origin rpy="0 0 0" xyz="0.2 0 0"/>
        <geometry>
          <sphere radius="0.015"/>
        </geometry>
      </collision>
    </collision>
  </link>
  <!-- leg position -->
  <joint name="leg_center_joint_LM" type="fixed">
    <origin rpy="0 0 0" xyz="0.0 0.08335 0"/>
    <parent link="base_link"/>
    <child link="leg_center_LM"/>
  </joint>
  <link name="leg_center_LM">
    <inertial>
      <origin rpy="0 0 0" xyz="0 0 0"/>
      <mass value="0.5"/>
      <inertia ixx="0.569270833333" ixy="0" ixz="0" iyy="2.63648666667" iyz="0" izz="2.63648666667"/>
    </inertial>
  </link>
  <!-- coxa -->
  <joint name="coxa_joint_LM" type="revolute">
    <origin rpy="0 0 1.57079632679" xyz="0 0 0"/>
    <parent link="leg_center_LM"/>
    <child link="coxa_LM"/>
    <axis xyz="0 0 -1"/>
    <limit effort="10000" lower="-3.14" upper="3.14" velocity="100"/>
  </joint>
  <link name="coxa_LM">
    <inertial>
      <origin rpy="0 0 0" xyz="0 0 0"/>
      <mass value="0.15"/>
      <inertia ixx="0.0096265625" ixy="0" ixz="0" iyy="0.093420185" iyz="0" izz="0.093420185"/>
    </inertial>
    <visual>
      <origin rpy="0 0 0" xyz="0.029465 0 0"/>
      <geometry>
        <box size="0.05893 0.022 0.0325"/>
      </geometry>
      <material name="">
        <color rgba="0.7 0.7 0.7 1"/>
      </material>
    </visual>
    <collision>
      <origin rpy="0 0 0" xyz="0.029465 0 0"/>
      <geometry>
        <box size="0.05893 0.022 0.0325"/>
      </geometry>
    </collision>
  </link>
  <!-- femur -->
  <joint name="femur_joint_LM" type="revolute">
    <origin rpy="-1.57079632679 +0.63 0" xyz="0.05893 0 0"/>
    <parent link="coxa_LM"/>
    <child link="femur_LM"/>
    <axis xyz="0 0 -1"/>
    <limit effort="10000" lower="-3.14" upper="3.14" velocity="100"/>
  </joint>
  <link name="femur_LM">
    <inertial>
      <origin rpy="0 0 0" xyz="0 -0.05399 0"/>
      <mass value="0.15"/>
      <inertia ixx="0.079474565" ixy="0" ixz="0" iyy="0.0096265625" iyz="0" izz="0.0096265625"/>
    </inertial>
    <visual>
      <origin rpy="0 0 0" xyz="0 -0.05399 0"/>
      <geometry>
        <box size="0.022 0.10798 0.0325"/>
      </geometry>
      <material name="">
        <color rgba="0.7 0.7 0.7 1"/>
      </material>
    </visual>
    <collision>
      <origin rpy="0 0 0" xyz="0 -0.05399 0"/>
      <geometry>
        <box size="0.022 0.10798 0.0325"/>
      </geometry>
    </collision>
  </link>
  <!-- tibia -->
  <joint name="tibia_joint_LM" type="revolute">
    <origin rpy="3.14159265359 0 0.63" xyz="0 -0.10798 0"/>
    <parent link="femur_LM"/>
    <child link="tibia_LM"/>
    <axis xyz="0 0 -1"/>
    <limit effort="10000" lower="-3.14" upper="3.14" velocity="100"/>
  </joint>
  <link name="tibia_LM">
    <inertial>
      <origin rpy="0 0 0" xyz="0.1 0 0"/>
      <mass value="0.15"/>
      <inertia ixx="0.0096265625" ixy="0" ixz="0" iyy="0.2566015625" iyz="0" izz="0.2566015625"/>
    </inertial>
    <visual>
      <origin rpy="0 0 0" xyz="0.1 0 0"/>
      <geometry>
        <box size="0.2 0.022 0.0325"/>
      </geometry>
      <material name="">
        <color rgba="0.7 0.7 0.7 1"/>
      </material>
    </visual>
    <visual>
      <origin rpy="0 0 0" xyz="0.2 0 0"/>
      <geometry>
        <sphere radius="0.015"/>
      </geometry>
      <material name="">
        <color rgba="0.7 0.7 0.7 1"/>
      </material>
    </visual>
    <collision>
      <origin rpy="0 0 0" xyz="0.1 0 0"/>
      <geometry>
        <box size="0.2 0.022 0.0325"/>
      </geometry>
      <collision>
        <origin rpy="0 0 0" xyz="0.2 0 0"/>
        <geometry>
          <sphere radius="0.015"/>
        </geometry>
      </collision>
    </collision>
  </link>
  <!-- leg position -->
  <joint name="leg_center_joint_LF" type="fixed">
    <origin rpy="0 0 0" xyz="-0.1778 0.08335 0"/>
    <parent link="base_link"/>
    <child link="leg_center_LF"/>
  </joint>
  <link name="leg_center_LF">
    <inertial>
      <origin rpy="0 0 0" xyz="0 0 0"/>
      <mass value="0.5"/>
      <inertia ixx="0.569270833333" ixy="0" ixz="0" iyy="2.63648666667" iyz="0" izz="2.63648666667"/>
    </inertial>
  </link>
  <!-- coxa -->
  <joint name="coxa_joint_LF" type="revolute">
    <origin rpy="0 0 1.57079632679" xyz="0 0 0"/>
    <parent link="leg_center_LF"/>
    <child link="coxa_LF"/>
    <axis xyz="0 0 -1"/>
    <limit effort="10000" lower="-3.14" upper="3.14" velocity="100"/>
  </joint>
  <link name="coxa_LF">
    <inertial>
      <origin rpy="0 0 0" xyz="0 0 0"/>
      <mass value="0.15"/>
      <inertia ixx="0.0096265625" ixy="0" ixz="0" iyy="0.093420185" iyz="0" izz="0.093420185"/>
    </inertial>
    <visual>
      <origin rpy="0 0 0" xyz="0.029465 0 0"/>
      <geometry>
        <box size="0.05893 0.022 0.0325"/>
      </geometry>
      <material name="">
        <color rgba="0.7 0.7 0.7 1"/>
      </material>
    </visual>
    <collision>
      <origin rpy="0 0 0" xyz="0.029465 0 0"/>
      <geometry>
        <box size="0.05893 0.022 0.0325"/>
      </geometry>
    </collision>
  </link>
  <!-- femur -->
  <joint name="femur_joint_LF" type="revolute">
    <origin rpy="-1.57079632679 +0.63 0" xyz="0.05893 0 0"/>
    <parent link="coxa_LF"/>
    <child link="femur_LF"/>
    <axis xyz="0 0 -1"/>
    <limit effort="10000" lower="-3.14" upper="3.14" velocity="100"/>
  </joint>
  <link name="femur_LF">
    <inertial>
      <origin rpy="0 0 0" xyz="0 -0.05399 0"/>
      <mass value="0.15"/>
      <inertia ixx="0.079474565" ixy="0" ixz="0" iyy="0.0096265625" iyz="0" izz="0.0096265625"/>
    </inertial>
    <visual>
      <origin rpy="0 0 0" xyz="0 -0.05399 0"/>
      <geometry>
        <box size="0.022 0.10798 0.0325"/>
      </geometry>
      <material name="">
        <color rgba="0.7 0.7 0.7 1"/>
      </material>
    </visual>
    <collision>
      <origin rpy="0 0 0" xyz="0 -0.05399 0"/>
      <geometry>
        <box size="0.022 0.10798 0.0325"/>
      </geometry>
    </collision>
  </link>
  <!-- tibia -->
  <joint name="tibia_joint_LF" type="revolute">
    <origin rpy="3.14159265359 0 0.63" xyz="0 -0.10798 0"/>
    <parent link="femur_LF"/>
    <child link="tibia_LF"/>
    <axis xyz="0 0 -1"/>
    <limit effort="10000" lower="-3.14" upper="3.14" velocity="100"/>
  </joint>
  <link name="tibia_LF">
    <inertial>
      <origin rpy="0 0 0" xyz="0.1 0 0"/>
      <mass value="0.15"/>
      <inertia ixx="0.0096265625" ixy="0" ixz="0" iyy="0.2566015625" iyz="0" izz="0.2566015625"/>
    </inertial>
    <visual>
      <origin rpy="0 0 0" xyz="0.1 0 0"/>
      <geometry>
        <box size="0.2 0.022 0.0325"/>
      </geometry>
      <material name="">
        <color rgba="0.7 0.7 0.7 1"/>
      </material>
    </visual>
    <visual>
      <origin rpy="0 0 0" xyz="0.2 0 0"/>
      <geometry>
        <sphere radius="0.015"/>
      </geometry>
      <material name="">
        <color rgba="0.7 0.7 0.7 1"/>
      </material>
    </visual>
    <collision>
      <origin rpy="0 0 0" xyz="0.1 0 0"/>
      <geometry>
        <box size="0.2 0.022 0.0325"/>
      </geometry>
      <collision>
        <origin rpy="0 0 0" xyz="0.2 0 0"/>
        <geometry>
          <sphere radius="0.015"/>
        </geometry>
      </collision>
    </collision>
  </link>
</robot>
