<?xml version="1.0" ?>
<!-- =================================================================================== -->
<!-- |    This document was autogenerated by xacro from /home/kaiser/WS_ROS/ws_tfg/src/bipedo/bipedo_description/urdf/bipedo.xacro | -->
<!-- |    EDITING THIS FILE BY HAND IS NOT RECOMMENDED                                 | -->
<!-- =================================================================================== -->
<robot name="piernas" xmlns:xacro="http://ros.org/wiki/xacro">
  <!-- en kg-->
  <link name="map"/>
  <joint name="map" type="fixed">
    <origin rpy="0 0 0" xyz="0 0 0"/>
    <parent link="map"/>
    <child link="base_link"/>
  </joint>
  <link name="base_link">
    <inertial>
      <origin rpy="0 0 0" xyz="0 0 0"/>
      <mass value="8"/>
      <inertia ixx="0.0188533333333" ixy="0" ixz="0" iyy="0.262686666667" iyz="0" izz="0.262686666667"/>
    </inertial>
    <visual>
      <origin rpy="0 0 0" xyz="0 0 0"/>
      <geometry>
        <box size="0.15 0.04 0.004"/>
      </geometry>
      <material name="">
        <color rgba="0.5 0.5 0.5 1"/>
      </material>
    </visual>
    <collision>
      <origin rpy="0 0 0" xyz="0 0 0"/>
      <geometry>
        <box size="0.15 0.04 0.004"/>
      </geometry>
    </collision>
  </link>
  <!--<xacro:macro name="pierna" params="side side2">
	<xacro:servo side="base"  side2="box" angulo="-${pi/2}"/>
</xacro:macro>-->
  <!-- Build robot model -->
  <!-- <xacro:pierna side="base_link"  side2="2"/>-->
  <joint name="base_box1_izq_joint" type="fixed">
    <origin rpy="0 0 0" xyz="0.055 0 -0.004"/>
    <parent link="base_link"/>
    <child link="box1_izq_link"/>
    <axis xyz="0 0 0"/>
    <limit effort="10000000000000000" lower="-2.5" upper="2.5" velocity="10000000000000000"/>
  </joint>
  <link name="box1_izq_link">
    <inertial>
      <origin rpy="0 0 0" xyz="0 0 0"/>
      <mass value="1.75"/>
      <inertia ixx="0.00235666666667" ixy="0" ixz="0" iyy="0.00235666666667" iyz="0" izz="0.00235666666667"/>
    </inertial>
    <inertial>
      <origin rpy="0 0 0" xyz="0.11 2.7756E-17 1.3293E-50"/>
      <mass value="0.35"/>
      <inertia ixx="0.0024325" ixy="0" ixz="0" iyy="$50*{m*(3*r*r+h*h)/12}" iyz="0" izz="0.00224"/>
    </inertial>
    <visual>
      <origin rpy="0 0 0" xyz="0 0 0"/>
      <geometry>
        <box size="0.04 0.04 0.004"/>
      </geometry>
      <material name="">
        <color rgba="0.79216 0 0.93333 1"/>
      </material>
    </visual>
    <visual>
      <origin rpy="0 0 1.57079632679" xyz="0 0 -0.013"/>
      <geometry>
        <cylinder length="0.03" radius="0.016"/>
      </geometry>
      <material name="">
        <color rgba="1 0 0 1"/>
      </material>
    </visual>
    <collision>
      <origin rpy="0 0 0" xyz="0 0 0"/>
      <geometry>
        <box size="0.008 0.008 0.0008"/>
      </geometry>
    </collision>
    <collision>
      <origin rpy="0 0 1.57079632679" xyz="0 0 -0.013"/>
      <geometry>
        <cylinder length="0.006" radius="0.0032"/>
      </geometry>
    </collision>
  </link>
  <joint name="cilinder_blue_box1_izq_joint" type="revolute">
    <origin rpy="0 0 0" xyz="0 0 -0.017"/>
    <parent link="box1_izq_link"/>
    <child link="blue_box1_izq_link"/>
    <axis xyz="0 0 1"/>
    <limit effort="10000000000000000" lower="-2.5" upper="2.5" velocity="10000000000000000"/>
  </joint>
  <link name="blue_box1_izq_link">
    <inertial>
      <origin rpy="0 0 0" xyz="0 0 0"/>
      <mass value="1.75"/>
      <inertia ixx="0.00235666666667" ixy="0" ixz="0" iyy="0.00235666666667" iyz="0" izz="0.00235666666667"/>
    </inertial>
    <visual>
      <origin rpy="0 0 0" xyz="0 0 -0.013"/>
      <geometry>
        <box size="0.04 0.04 0.004"/>
      </geometry>
      <material name="">
        <color rgba="0 0 1 1"/>
      </material>
    </visual>
    <collision>
      <origin rpy="0 0 0" xyz="0 0 -0.013"/>
      <geometry>
        <box size="0.04 0.04 0.004"/>
      </geometry>
    </collision>
  </link>
  <joint name="blue_box1_izq_box2_izq_joint" type="fixed">
    <origin rpy="0 0 0" xyz="0 0 -0.017"/>
    <parent link="blue_box1_izq_link"/>
    <child link="box2_izq_link"/>
    <axis xyz="0 0 0"/>
    <limit effort="10000000000000000" lower="-2.5" upper="2.5" velocity="10000000000000000"/>
  </joint>
  <link name="box2_izq_link">
    <inertial>
      <origin rpy="0 0 0" xyz="0 0 0"/>
      <mass value="0.35"/>
      <inertia ixx="0.00235666666667" ixy="0" ixz="0" iyy="0.00235666666667" iyz="0" izz="0.00235666666667"/>
    </inertial>
    <inertial>
      <origin rpy="0 0 0" xyz="0.11 2.7756E-17 1.3293E-50"/>
      <mass value="0.35"/>
      <inertia ixx="0.0024325" ixy="0" ixz="0" iyy="$50*{m*(3*r*r+h*h)/12}" iyz="0" izz="0.00224"/>
    </inertial>
    <visual>
      <origin rpy="0 0 0" xyz="0 0 0"/>
      <geometry>
        <box size="0.04 0.04 0.004"/>
      </geometry>
      <material name="">
        <color rgba="0.79216 0 0.93333 1"/>
      </material>
    </visual>
    <visual>
      <origin rpy="1.57079632679 0 1.57079632679" xyz="0 0 -0.014"/>
      <geometry>
        <cylinder length="0.03" radius="0.016"/>
      </geometry>
      <material name="">
        <color rgba="1 0 0 1"/>
      </material>
    </visual>
    <collision>
      <origin rpy="0 0 0" xyz="0 0 0"/>
      <geometry>
        <box size="0.04 0.04 0.004"/>
      </geometry>
    </collision>
    <collision>
      <origin rpy="1.57079632679 0 0" xyz="0 0 -0.014"/>
      <geometry>
        <cylinder length="0.009" radius="0.0048"/>
      </geometry>
    </collision>
  </link>
  <joint name="cilinder_blue1_box2_izq_joint" type="revolute">
    <origin rpy="0 0 0" xyz="0 0 -0.014"/>
    <parent link="box2_izq_link"/>
    <child link="auxiliarbox2_izq"/>
    <axis xyz="0 1 0"/>
    <limit effort="10000000000000000" lower="-2.5" upper="2.5" velocity="10000000000000000"/>
  </joint>
  <link name="auxiliarbox2_izq">
    <inertial>
      <origin rpy="0 0 0" xyz="0 0 0"/>
      <mass value="0.35"/>
      <inertia ixx="0.0" ixy="0" ixz="0" iyy="0.0" iyz="0" izz="0.0"/>
    </inertial>
    <visual>
      <origin rpy="1.57079632679 0 0" xyz="0 0 0"/>
      <geometry>
        <cylinder length="0.03" radius="0.016"/>
      </geometry>
      <material name="">
        <color rgba="1 0 0 1"/>
      </material>
    </visual>
    <collision>
      <origin rpy="1.57079632679 0 1.57079632679" xyz="0 0 0"/>
      <geometry>
        <cylinder length="0.009" radius="0.0048"/>
      </geometry>
    </collision>
  </link>
  <joint name="cilinder_blue_box2_izq_joint" type="revolute">
    <origin rpy="0 0 0" xyz="0 0 0"/>
    <parent link="auxiliarbox2_izq"/>
    <child link="blue_box2_izq_link"/>
    <axis xyz="1 0 0"/>
    <limit effort="10000000000000000" lower="-2.5" upper="2.5" velocity="10000000000000000"/>
  </joint>
  <link name="blue_box2_izq_link">
    <inertial>
      <origin rpy="0 0 0" xyz="0 0 0"/>
      <mass value="0.35"/>
      <inertia ixx="0.00235666666667" ixy="0" ixz="0" iyy="0.00235666666667" iyz="0" izz="0.00235666666667"/>
    </inertial>
    <visual>
      <origin rpy="0 0 0" xyz="0 0 -0.014"/>
      <geometry>
        <box size="0.04 0.04 0.004"/>
      </geometry>
      <material name="">
        <color rgba="0 0 1 1"/>
      </material>
    </visual>
    <collision>
      <origin rpy="0 0 0" xyz="0 0 -0.014"/>
      <geometry>
        <box size="0.04 0.04 0.004"/>
      </geometry>
    </collision>
  </link>
  <joint name="blue_box2_izq_box3_izq_joint" type="fixed">
    <origin rpy="0 0 0" xyz="0 0 -0.041"/>
    <parent link="blue_box2_izq_link"/>
    <child link="box3_izq_link"/>
    <axis xyz="0 0 0"/>
    <limit effort="10000000000000000" lower="-2.5" upper="2.5" velocity="10000000000000000"/>
  </joint>
  <link name="box3_izq_link">
    <inertial>
      <origin rpy="0 0 0" xyz="0 0 0"/>
      <mass value="0.35"/>
      <inertia ixx="0.00235666666667" ixy="0" ixz="0" iyy="0.00235666666667" iyz="0" izz="0.00235666666667"/>
    </inertial>
    <visual>
      <origin rpy="0 0 0" xyz="0 0 0"/>
      <geometry>
        <box size="0.04 0.04 0.05"/>
      </geometry>
      <material name="">
        <color rgba="0.79216 0 0.93333 1"/>
      </material>
    </visual>
    <collision>
      <origin rpy="0 0 0" xyz="0 0 0"/>
      <geometry>
        <box size="0.04 0.04 0.05"/>
      </geometry>
    </collision>
  </link>
  <joint name="box3_izq_box4_izq_joint" type="fixed">
    <origin rpy="0 0 0" xyz="0 0 -0.025"/>
    <parent link="box3_izq_link"/>
    <child link="box4_izq_link"/>
    <axis xyz="0 0 0"/>
    <limit effort="10000000000000000" lower="-2.5" upper="2.5" velocity="10000000000000000"/>
  </joint>
  <link name="box4_izq_link">
    <inertial>
      <origin rpy="0 0 0" xyz="0 0 0"/>
      <mass value="0.35"/>
      <inertia ixx="0.00235666666667" ixy="0" ixz="0" iyy="0.00235666666667" iyz="0" izz="0.00235666666667"/>
    </inertial>
    <inertial>
      <origin rpy="0 0 0" xyz="0.11 2.7756E-17 1.3293E-50"/>
      <mass value="0.35"/>
      <inertia ixx="0.0024325" ixy="0" ixz="0" iyy="$50*{m*(3*r*r+h*h)/12}" iyz="0" izz="0.00224"/>
    </inertial>
    <visual>
      <origin rpy="0 0 0" xyz="0 0 0"/>
      <geometry>
        <box size="0.04 0.04 0.004"/>
      </geometry>
      <material name="">
        <color rgba="0.79216 0 0.93333 1"/>
      </material>
    </visual>
    <visual>
      <origin rpy="1.57079632679 0 1.57079632679" xyz="0 0 -0.014"/>
      <geometry>
        <cylinder length="0.03" radius="0.016"/>
      </geometry>
      <material name="">
        <color rgba="1 0 0 1"/>
      </material>
    </visual>
    <collision>
      <origin rpy="0 0 0" xyz="0 0 0"/>
      <geometry>
        <box size="0.04 0.04 0.004"/>
      </geometry>
    </collision>
    <collision>
      <origin rpy="1.57079632679 0 1.57079632679" xyz="0 0 -0.014"/>
      <geometry>
        <cylinder length="0.03" radius="0.016"/>
      </geometry>
    </collision>
  </link>
  <joint name="cilinder_blue_box4_izq_joint" type="revolute">
    <origin rpy="0 0 0" xyz="0 0 -0.014"/>
    <parent link="box4_izq_link"/>
    <child link="blue_box4_izq_link"/>
    <axis xyz="1 0 0"/>
    <limit effort="10000000000000000" lower="-2.5" upper="2.5" velocity="10000000000000000"/>
  </joint>
  <link name="blue_box4_izq_link">
    <inertial>
      <origin rpy="0 0 0" xyz="0 0 0"/>
      <mass value="0.35"/>
      <inertia ixx="0.00235666666667" ixy="0" ixz="0" iyy="0.00235666666667" iyz="0" izz="0.00235666666667"/>
    </inertial>
    <visual>
      <origin rpy="0 0 0" xyz="0 0 -0.014"/>
      <geometry>
        <box size="0.04 0.04 0.004"/>
      </geometry>
      <material name="">
        <color rgba="0 0 1 1"/>
      </material>
    </visual>
    <collision>
      <origin rpy="0 0 0" xyz="0 0 -0.014"/>
      <geometry>
        <box size="0.04 0.04 0.004"/>
      </geometry>
    </collision>
  </link>
  <joint name="blue_box4_izq_box5_izq_joint" type="fixed">
    <origin rpy="0 0 0" xyz="0 0 -0.041"/>
    <parent link="blue_box4_izq_link"/>
    <child link="box5_izq_link"/>
    <axis xyz="0 0 0"/>
    <limit effort="10000000000000000" lower="-2.5" upper="2.5" velocity="10000000000000000"/>
  </joint>
  <link name="box5_izq_link">
    <inertial>
      <origin rpy="0 0 0" xyz="0 0 0"/>
      <mass value="0.35"/>
      <inertia ixx="0.00235666666667" ixy="0" ixz="0" iyy="0.00235666666667" iyz="0" izz="0.00235666666667"/>
    </inertial>
    <visual>
      <origin rpy="0 0 0" xyz="0 0 0"/>
      <geometry>
        <box size="0.04 0.04 0.05"/>
      </geometry>
      <material name="">
        <color rgba="0.79216 0 0.93333 1"/>
      </material>
    </visual>
    <collision>
      <origin rpy="0 0 0" xyz="0 0 0"/>
      <geometry>
        <box size="0.04 0.04 0.05"/>
      </geometry>
    </collision>
  </link>
  <joint name="box5_izq_box6_izq_joint" type="fixed">
    <origin rpy="0 0 0" xyz="0 0 -0.025"/>
    <parent link="box5_izq_link"/>
    <child link="box6_izq_link"/>
    <axis xyz="0 0 0"/>
    <limit effort="10000000000000000" lower="-2.5" upper="2.5" velocity="10000000000000000"/>
  </joint>
  <link name="box6_izq_link">
    <inertial>
      <origin rpy="0 0 0" xyz="0 0 0"/>
      <mass value="0.35"/>
      <inertia ixx="0.00235666666667" ixy="0" ixz="0" iyy="0.00235666666667" iyz="0" izz="0.00235666666667"/>
    </inertial>
    <inertial>
      <origin rpy="0 0 0" xyz="0.11 2.7756E-17 1.3293E-50"/>
      <mass value="0.35"/>
      <inertia ixx="0.0024325" ixy="0" ixz="0" iyy="$50*{m*(3*r*r+h*h)/12}" iyz="0" izz="0.00224"/>
    </inertial>
    <visual>
      <origin rpy="0 0 0" xyz="0 0 0"/>
      <geometry>
        <box size="0.04 0.04 0.004"/>
      </geometry>
      <material name="">
        <color rgba="0.79216 0 0.93333 1"/>
      </material>
    </visual>
    <visual>
      <origin rpy="1.57079632679 0 1.57079632679" xyz="0 0 -0.014"/>
      <geometry>
        <cylinder length="0.03" radius="0.016"/>
      </geometry>
      <material name="">
        <color rgba="1 0 0 1"/>
      </material>
    </visual>
    <collision>
      <origin rpy="0 0 0" xyz="0 0 0"/>
      <geometry>
        <box size="0.04 0.04 0.004"/>
      </geometry>
    </collision>
    <collision>
      <origin rpy="1.57079632679 0 0" xyz="0 0 -0.014"/>
      <geometry>
        <cylinder length="0.009" radius="0.0048"/>
      </geometry>
    </collision>
  </link>
  <joint name="cilinder_blue1_box6_izq_joint" type="revolute">
    <origin rpy="0 0 0" xyz="0 0 -0.014"/>
    <parent link="box6_izq_link"/>
    <child link="auxiliarbox6_izq"/>
    <axis xyz="0 1 0"/>
    <limit effort="10000000000000000" lower="-2.5" upper="2.5" velocity="10000000000000000"/>
  </joint>
  <link name="auxiliarbox6_izq">
    <inertial>
      <origin rpy="0 0 0" xyz="0 0 0"/>
      <mass value="0.35"/>
      <inertia ixx="0.0" ixy="0" ixz="0" iyy="0.0" iyz="0" izz="0.0"/>
    </inertial>
    <visual>
      <origin rpy="1.57079632679 0 0" xyz="0 0 0"/>
      <geometry>
        <cylinder length="0.03" radius="0.016"/>
      </geometry>
      <material name="">
        <color rgba="1 0 0 1"/>
      </material>
    </visual>
    <collision>
      <origin rpy="1.57079632679 0 1.57079632679" xyz="0 0 0"/>
      <geometry>
        <cylinder length="0.009" radius="0.0048"/>
      </geometry>
    </collision>
  </link>
  <joint name="cilinder_blue_box6_izq_joint" type="revolute">
    <origin rpy="0 0 0" xyz="0 0 0"/>
    <parent link="auxiliarbox6_izq"/>
    <child link="blue_box6_izq_link"/>
    <axis xyz="1 0 0"/>
    <limit effort="10000000000000000" lower="-2.5" upper="2.5" velocity="10000000000000000"/>
  </joint>
  <link name="blue_box6_izq_link">
    <inertial>
      <origin rpy="0 0 0" xyz="0 0 0"/>
      <mass value="0.35"/>
      <inertia ixx="0.00235666666667" ixy="0" ixz="0" iyy="0.00235666666667" iyz="0" izz="0.00235666666667"/>
    </inertial>
    <visual>
      <origin rpy="0 0 0" xyz="0 0 -0.014"/>
      <geometry>
        <box size="0.04 0.04 0.004"/>
      </geometry>
      <material name="">
        <color rgba="0 0 1 1"/>
      </material>
    </visual>
    <collision>
      <origin rpy="0 0 0" xyz="0 0 -0.014"/>
      <geometry>
        <box size="0.04 0.04 0.004"/>
      </geometry>
    </collision>
  </link>
  <joint name="blue_box6_izq_pie_izq_joint" type="fixed">
    <origin rpy="0 0 0" xyz="0 0 -0.018"/>
    <parent link="blue_box6_izq_link"/>
    <child link="pie_izq_link"/>
    <axis xyz="0 0 0"/>
    <limit effort="100" lower="-2.5" upper="2.5" velocity="10000000000000000"/>
  </joint>
  <link name="pie_izq_link">
    <inertial>
      <origin rpy="0 0 0" xyz="0 0 0"/>
      <mass value="0.35"/>
      <inertia ixx="0.00935666666667" ixy="0" ixz="0" iyy="0.00935666666667" iyz="0" izz="0.00935666666667"/>
    </inertial>
    <visual>
      <origin rpy="0 0 0" xyz="0 0 0"/>
      <geometry>
        <box size="0.1 0.16 0.004"/>
      </geometry>
      <material name="">
        <color rgba="0.79216 0 0.93333 1"/>
      </material>
    </visual>
    <collision>
      <origin rpy="0 0 0" xyz="0 0 0"/>
      <geometry>
        <box size="0.12 0.16 0.004"/>
      </geometry>
    </collision>
  </link>
  <joint name="base_box1_der_joint" type="fixed">
    <origin rpy="0 0 0" xyz="-0.055 0 -0.004"/>
    <parent link="base_link"/>
    <child link="box1_der_link"/>
    <axis xyz="0 0 0"/>
    <limit effort="10000000000000000" lower="-2.5" upper="2.5" velocity="10000000000000000"/>
  </joint>
  <link name="box1_der_link">
    <inertial>
      <origin rpy="0 0 0" xyz="0 0 0"/>
      <mass value="1.75"/>
      <inertia ixx="0.00235666666667" ixy="0" ixz="0" iyy="0.00235666666667" iyz="0" izz="0.00235666666667"/>
    </inertial>
    <inertial>
      <origin rpy="0 0 0" xyz="0.11 2.7756E-17 1.3293E-50"/>
      <mass value="0.35"/>
      <inertia ixx="0.0024325" ixy="0" ixz="0" iyy="$50*{m*(3*r*r+h*h)/12}" iyz="0" izz="0.00224"/>
    </inertial>
    <visual>
      <origin rpy="0 0 0" xyz="0 0 0"/>
      <geometry>
        <box size="0.04 0.04 0.004"/>
      </geometry>
      <material name="">
        <color rgba="0.79216 0 0.93333 1"/>
      </material>
    </visual>
    <visual>
      <origin rpy="0 0 1.57079632679" xyz="0 0 -0.013"/>
      <geometry>
        <cylinder length="0.03" radius="0.016"/>
      </geometry>
      <material name="">
        <color rgba="1 0 0 1"/>
      </material>
    </visual>
    <collision>
      <origin rpy="0 0 0" xyz="0 0 0"/>
      <geometry>
        <box size="0.008 0.008 0.0008"/>
      </geometry>
    </collision>
    <collision>
      <origin rpy="0 0 1.57079632679" xyz="0 0 -0.013"/>
      <geometry>
        <cylinder length="0.006" radius="0.0032"/>
      </geometry>
    </collision>
  </link>
  <joint name="cilinder_blue_box1_der_joint" type="revolute">
    <origin rpy="0 0 0" xyz="0 0 -0.017"/>
    <parent link="box1_der_link"/>
    <child link="blue_box1_der_link"/>
    <axis xyz="0 0 1"/>
    <limit effort="10000000000000000" lower="-2.5" upper="2.5" velocity="10000000000000000"/>
  </joint>
  <link name="blue_box1_der_link">
    <inertial>
      <origin rpy="0 0 0" xyz="0 0 0"/>
      <mass value="1.75"/>
      <inertia ixx="0.00235666666667" ixy="0" ixz="0" iyy="0.00235666666667" iyz="0" izz="0.00235666666667"/>
    </inertial>
    <visual>
      <origin rpy="0 0 0" xyz="0 0 -0.013"/>
      <geometry>
        <box size="0.04 0.04 0.004"/>
      </geometry>
      <material name="">
        <color rgba="0 0 1 1"/>
      </material>
    </visual>
    <collision>
      <origin rpy="0 0 0" xyz="0 0 -0.013"/>
      <geometry>
        <box size="0.04 0.04 0.004"/>
      </geometry>
    </collision>
  </link>
  <joint name="blue_box1_der_box2_der_joint" type="fixed">
    <origin rpy="0 0 0" xyz="0 0 -0.018"/>
    <parent link="blue_box1_der_link"/>
    <child link="box2_der_link"/>
    <axis xyz="0 0 0"/>
    <limit effort="10000000000000000" lower="-2.5" upper="2.5" velocity="10000000000000000"/>
  </joint>
  <link name="box2_der_link">
    <inertial>
      <origin rpy="0 0 0" xyz="0 0 0"/>
      <mass value="0.35"/>
      <inertia ixx="0.00235666666667" ixy="0" ixz="0" iyy="0.00235666666667" iyz="0" izz="0.00235666666667"/>
    </inertial>
    <inertial>
      <origin rpy="0 0 0" xyz="0.11 2.7756E-17 1.3293E-50"/>
      <mass value="0.35"/>
      <inertia ixx="0.0024325" ixy="0" ixz="0" iyy="$50*{m*(3*r*r+h*h)/12}" iyz="0" izz="0.00224"/>
    </inertial>
    <visual>
      <origin rpy="0 0 0" xyz="0 0 0"/>
      <geometry>
        <box size="0.04 0.04 0.004"/>
      </geometry>
      <material name="">
        <color rgba="0.79216 0 0.93333 1"/>
      </material>
    </visual>
    <visual>
      <origin rpy="1.57079632679 0 1.57079632679" xyz="0 0 -0.014"/>
      <geometry>
        <cylinder length="0.03" radius="0.016"/>
      </geometry>
      <material name="">
        <color rgba="1 0 0 1"/>
      </material>
    </visual>
    <collision>
      <origin rpy="0 0 0" xyz="0 0 0"/>
      <geometry>
        <box size="0.04 0.04 0.004"/>
      </geometry>
    </collision>
    <collision>
      <origin rpy="1.57079632679 0 0" xyz="0 0 -0.014"/>
      <geometry>
        <cylinder length="0.009" radius="0.0048"/>
      </geometry>
    </collision>
  </link>
  <joint name="cilinder_blue1_box2_der_joint" type="revolute">
    <origin rpy="0 0 0" xyz="0 0 -0.014"/>
    <parent link="box2_der_link"/>
    <child link="auxiliarbox2_der"/>
    <axis xyz="0 1 0"/>
    <limit effort="10000000000000000" lower="-2.5" upper="2.5" velocity="10000000000000000"/>
  </joint>
  <link name="auxiliarbox2_der">
    <inertial>
      <origin rpy="0 0 0" xyz="0 0 0"/>
      <mass value="0.35"/>
      <inertia ixx="0.0" ixy="0" ixz="0" iyy="0.0" iyz="0" izz="0.0"/>
    </inertial>
    <visual>
      <origin rpy="1.57079632679 0 0" xyz="0 0 0"/>
      <geometry>
        <cylinder length="0.03" radius="0.016"/>
      </geometry>
      <material name="">
        <color rgba="1 0 0 1"/>
      </material>
    </visual>
    <collision>
      <origin rpy="1.57079632679 0 1.57079632679" xyz="0 0 0"/>
      <geometry>
        <cylinder length="0.009" radius="0.0048"/>
      </geometry>
    </collision>
  </link>
  <joint name="cilinder_blue_box2_der_joint" type="revolute">
    <origin rpy="0 0 0" xyz="0 0 0"/>
    <parent link="auxiliarbox2_der"/>
    <child link="blue_box2_der_link"/>
    <axis xyz="1 0 0"/>
    <limit effort="10000000000000000" lower="-2.5" upper="2.5" velocity="10000000000000000"/>
  </joint>
  <link name="blue_box2_der_link">
    <inertial>
      <origin rpy="0 0 0" xyz="0 0 0"/>
      <mass value="0.35"/>
      <inertia ixx="0.00235666666667" ixy="0" ixz="0" iyy="0.00235666666667" iyz="0" izz="0.00235666666667"/>
    </inertial>
    <visual>
      <origin rpy="0 0 0" xyz="0 0 -0.014"/>
      <geometry>
        <box size="0.04 0.04 0.004"/>
      </geometry>
      <material name="">
        <color rgba="0 0 1 1"/>
      </material>
    </visual>
    <collision>
      <origin rpy="0 0 0" xyz="0 0 -0.014"/>
      <geometry>
        <box size="0.04 0.04 0.004"/>
      </geometry>
    </collision>
  </link>
  <joint name="blue_box2_der_box3_der_joint" type="fixed">
    <origin rpy="0 0 0" xyz="0 0 -0.04"/>
    <parent link="blue_box2_der_link"/>
    <child link="box3_der_link"/>
    <axis xyz="0 0 0"/>
    <limit effort="10000000000000000" lower="-2.5" upper="2.5" velocity="10000000000000000"/>
  </joint>
  <link name="box3_der_link">
    <inertial>
      <origin rpy="0 0 0" xyz="0 0 0"/>
      <mass value="0.35"/>
      <inertia ixx="0.00235666666667" ixy="0" ixz="0" iyy="0.00235666666667" iyz="0" izz="0.00235666666667"/>
    </inertial>
    <visual>
      <origin rpy="0 0 0" xyz="0 0 0"/>
      <geometry>
        <box size="0.04 0.04 0.05"/>
      </geometry>
      <material name="">
        <color rgba="0.79216 0 0.93333 1"/>
      </material>
    </visual>
    <collision>
      <origin rpy="0 0 0" xyz="0 0 0"/>
      <geometry>
        <box size="0.04 0.04 0.05"/>
      </geometry>
    </collision>
  </link>
  <joint name="box3_der_box4_der_joint" type="fixed">
    <origin rpy="0 0 0" xyz="0 0 -0.025"/>
    <parent link="box3_der_link"/>
    <child link="box4_der_link"/>
    <axis xyz="0 0 0"/>
    <limit effort="10000000000000000" lower="-2.5" upper="2.5" velocity="10000000000000000"/>
  </joint>
  <link name="box4_der_link">
    <inertial>
      <origin rpy="0 0 0" xyz="0 0 0"/>
      <mass value="0.35"/>
      <inertia ixx="0.00235666666667" ixy="0" ixz="0" iyy="0.00235666666667" iyz="0" izz="0.00235666666667"/>
    </inertial>
    <inertial>
      <origin rpy="0 0 0" xyz="0.11 2.7756E-17 1.3293E-50"/>
      <mass value="0.35"/>
      <inertia ixx="0.0024325" ixy="0" ixz="0" iyy="$50*{m*(3*r*r+h*h)/12}" iyz="0" izz="0.00224"/>
    </inertial>
    <visual>
      <origin rpy="0 0 0" xyz="0 0 0"/>
      <geometry>
        <box size="0.04 0.04 0.004"/>
      </geometry>
      <material name="">
        <color rgba="0.79216 0 0.93333 1"/>
      </material>
    </visual>
    <visual>
      <origin rpy="1.57079632679 0 1.57079632679" xyz="0 0 -0.014"/>
      <geometry>
        <cylinder length="0.03" radius="0.016"/>
      </geometry>
      <material name="">
        <color rgba="1 0 0 1"/>
      </material>
    </visual>
    <collision>
      <origin rpy="0 0 0" xyz="0 0 0"/>
      <geometry>
        <box size="0.04 0.04 0.004"/>
      </geometry>
    </collision>
    <collision>
      <origin rpy="1.57079632679 0 1.57079632679" xyz="0 0 -0.014"/>
      <geometry>
        <cylinder length="0.03" radius="0.016"/>
      </geometry>
    </collision>
  </link>
  <joint name="cilinder_blue_box4_der_joint" type="revolute">
    <origin rpy="0 0 0" xyz="0 0 -0.014"/>
    <parent link="box4_der_link"/>
    <child link="blue_box4_der_link"/>
    <axis xyz="1 0 0"/>
    <limit effort="10000000000000000" lower="-2.5" upper="2.5" velocity="10000000000000000"/>
  </joint>
  <link name="blue_box4_der_link">
    <inertial>
      <origin rpy="0 0 0" xyz="0 0 0"/>
      <mass value="0.35"/>
      <inertia ixx="0.00235666666667" ixy="0" ixz="0" iyy="0.00235666666667" iyz="0" izz="0.00235666666667"/>
    </inertial>
    <visual>
      <origin rpy="0 0 0" xyz="0 0 -0.014"/>
      <geometry>
        <box size="0.04 0.04 0.004"/>
      </geometry>
      <material name="">
        <color rgba="0 0 1 1"/>
      </material>
    </visual>
    <collision>
      <origin rpy="0 0 0" xyz="0 0 -0.014"/>
      <geometry>
        <box size="0.04 0.04 0.004"/>
      </geometry>
    </collision>
  </link>
  <joint name="blue_box4_der_box5_der_joint" type="fixed">
    <origin rpy="0 0 0" xyz="0 0 -0.041"/>
    <parent link="blue_box4_der_link"/>
    <child link="box5_der_link"/>
    <axis xyz="0 0 0"/>
    <limit effort="10000000000000000" lower="-2.5" upper="2.5" velocity="10000000000000000"/>
  </joint>
  <link name="box5_der_link">
    <inertial>
      <origin rpy="0 0 0" xyz="0 0 0"/>
      <mass value="0.35"/>
      <inertia ixx="0.00235666666667" ixy="0" ixz="0" iyy="0.00235666666667" iyz="0" izz="0.00235666666667"/>
    </inertial>
    <visual>
      <origin rpy="0 0 0" xyz="0 0 0"/>
      <geometry>
        <box size="0.04 0.04 0.05"/>
      </geometry>
      <material name="">
        <color rgba="0.79216 0 0.93333 1"/>
      </material>
    </visual>
    <collision>
      <origin rpy="0 0 0" xyz="0 0 0"/>
      <geometry>
        <box size="0.04 0.04 0.05"/>
      </geometry>
    </collision>
  </link>
  <joint name="box5_der_box6_der_joint" type="fixed">
    <origin rpy="0 0 0" xyz="0 0 -0.025"/>
    <parent link="box5_der_link"/>
    <child link="box6_der_link"/>
    <axis xyz="0 0 0"/>
    <limit effort="10000000000000000" lower="-2.5" upper="2.5" velocity="10000000000000000"/>
  </joint>
  <link name="box6_der_link">
    <inertial>
      <origin rpy="0 0 0" xyz="0 0 0"/>
      <mass value="0.35"/>
      <inertia ixx="0.00235666666667" ixy="0" ixz="0" iyy="0.00235666666667" iyz="0" izz="0.00235666666667"/>
    </inertial>
    <inertial>
      <origin rpy="0 0 0" xyz="0.11 2.7756E-17 1.3293E-50"/>
      <mass value="0.35"/>
      <inertia ixx="0.0024325" ixy="0" ixz="0" iyy="$50*{m*(3*r*r+h*h)/12}" iyz="0" izz="0.00224"/>
    </inertial>
    <visual>
      <origin rpy="0 0 0" xyz="0 0 0"/>
      <geometry>
        <box size="0.04 0.04 0.004"/>
      </geometry>
      <material name="">
        <color rgba="0.79216 0 0.93333 1"/>
      </material>
    </visual>
    <visual>
      <origin rpy="1.57079632679 0 1.57079632679" xyz="0 0 -0.014"/>
      <geometry>
        <cylinder length="0.03" radius="0.016"/>
      </geometry>
      <material name="">
        <color rgba="1 0 0 1"/>
      </material>
    </visual>
    <collision>
      <origin rpy="0 0 0" xyz="0 0 0"/>
      <geometry>
        <box size="0.04 0.04 0.004"/>
      </geometry>
    </collision>
    <collision>
      <origin rpy="1.57079632679 0 0" xyz="0 0 -0.014"/>
      <geometry>
        <cylinder length="0.009" radius="0.0048"/>
      </geometry>
    </collision>
  </link>
  <joint name="cilinder_blue1_box6_der_joint" type="revolute">
    <origin rpy="0 0 0" xyz="0 0 -0.014"/>
    <parent link="box6_der_link"/>
    <child link="auxiliarbox6_der"/>
    <axis xyz="0 1 0"/>
    <limit effort="10000000000000000" lower="-2.5" upper="2.5" velocity="10000000000000000"/>
  </joint>
  <link name="auxiliarbox6_der">
    <inertial>
      <origin rpy="0 0 0" xyz="0 0 0"/>
      <mass value="0.35"/>
      <inertia ixx="0.0" ixy="0" ixz="0" iyy="0.0" iyz="0" izz="0.0"/>
    </inertial>
    <visual>
      <origin rpy="1.57079632679 0 0" xyz="0 0 0"/>
      <geometry>
        <cylinder length="0.03" radius="0.016"/>
      </geometry>
      <material name="">
        <color rgba="1 0 0 1"/>
      </material>
    </visual>
    <collision>
      <origin rpy="1.57079632679 0 1.57079632679" xyz="0 0 0"/>
      <geometry>
        <cylinder length="0.009" radius="0.0048"/>
      </geometry>
    </collision>
  </link>
  <joint name="cilinder_blue_box6_der_joint" type="revolute">
    <origin rpy="0 0 0" xyz="0 0 0"/>
    <parent link="auxiliarbox6_der"/>
    <child link="blue_box6_der_link"/>
    <axis xyz="1 0 0"/>
    <limit effort="10000000000000000" lower="-2.5" upper="2.5" velocity="10000000000000000"/>
  </joint>
  <link name="blue_box6_der_link">
    <inertial>
      <origin rpy="0 0 0" xyz="0 0 0"/>
      <mass value="0.35"/>
      <inertia ixx="0.00235666666667" ixy="0" ixz="0" iyy="0.00235666666667" iyz="0" izz="0.00235666666667"/>
    </inertial>
    <visual>
      <origin rpy="0 0 0" xyz="0 0 -0.014"/>
      <geometry>
        <box size="0.04 0.04 0.004"/>
      </geometry>
      <material name="">
        <color rgba="0 0 1 1"/>
      </material>
    </visual>
    <collision>
      <origin rpy="0 0 0" xyz="0 0 -0.014"/>
      <geometry>
        <box size="0.04 0.04 0.004"/>
      </geometry>
    </collision>
  </link>
  <joint name="blue_box6_der_pie_der_joint" type="fixed">
    <origin rpy="0 0 0" xyz="0 0 -0.018"/>
    <parent link="blue_box6_der_link"/>
    <child link="pie_der_link"/>
    <axis xyz="0 0 0"/>
    <limit effort="100" lower="-2.5" upper="2.5" velocity="10000000000000000"/>
  </joint>
  <link name="pie_der_link">
    <inertial>
      <origin rpy="0 0 0" xyz="0 0 0"/>
      <mass value="0.35"/>
      <inertia ixx="0.00935666666667" ixy="0" ixz="0" iyy="0.00935666666667" iyz="0" izz="0.00935666666667"/>
    </inertial>
    <visual>
      <origin rpy="0 0 0" xyz="0 0 0"/>
      <geometry>
        <box size="0.1 0.16 0.004"/>
      </geometry>
      <material name="">
        <color rgba="0.79216 0 0.93333 1"/>
      </material>
    </visual>
    <collision>
      <origin rpy="0 0 0" xyz="0 0 0"/>
      <geometry>
        <box size="0.12 0.16 0.004"/>
      </geometry>
    </collision>
  </link>
  <!---->
</robot>
