<robot
  name="IRB120_URDF_v2">

<link name="world"/>
  <joint name="world-base_link-fixed" type="fixed">
    <parent link="world"/>
    <child link="base_link"/>
  </joint>

  <link
    name="base_link">
    <inertial>
      <origin
        xyz="0.000506829635586531 0.0164502533862307 0.0190436684467408"
        rpy="0 0 0" />
      <mass
        value="0.186710038823954" />
      <inertia
        ixx="0.000206749385902935"
        ixy="2.65903225922209E-07"
        ixz="-6.42188067979825E-07"
        iyy="0.000142370123394231"
        iyz="-1.88688437962842E-05"
        izz="0.000237642416130309" />
    </inertial>
    <visual>
      <origin
        xyz="0 0 0"
        rpy="0 0 0" />
      <geometry>
        <mesh
          filename="package://abb_irb_120_description/urdf/meshes_irb_120_grande/base_link.STL" />
      </geometry>
      <material
        name="">
        <color
          rgba="0.792156862745098 0.819607843137255 0.933333333333333 1" />
      </material>
    </visual>
    <collision>
      <origin
        xyz="0 0 0"
        rpy="0 0 0" />
      <geometry>
        <mesh
          filename="package://abb_irb_120_description/urdf/meshes_irb_120_grande/base_link.STL" />
      </geometry>
    </collision>
  </link>
  <link
    name="link_1">
    <inertial>
      <origin
        xyz="0.000101483490267508 -0.00014611402597127 0.123194805129936"
        rpy="0 0 0" />
      <mass
        value="0.13638834098729" />
      <inertia
        ixx="0.000566240771092216"
        ixy="1.69586492496761E-07"
        ixz="3.91940337671747E-07"
        iyy="0.000571596904478103"
        iyz="-9.71926251557855E-07"
        izz="2.69322962790034E-05" />
    </inertial>
    <visual>
      <origin
        xyz="0 0 0"
        rpy="0 0 0" />
      <geometry>
        <mesh
          filename="package://abb_irb_120_description/urdf/meshes_irb_120_grande/link_1.STL" />
      </geometry>
      <material
        name="">
        <color
          rgba="1 1 1 1" />
      </material>
    </visual>
    <collision>
      <origin
        xyz="0 0 0"
        rpy="0 0 0" />
      <geometry>
        <mesh
          filename="package://abb_irb_120_description/urdf/meshes_irb_120_grande/link_1.STL" />
      </geometry>
    </collision>
  </link>
  <joint
    name="joint_1"
    type="revolute">
    <origin
      xyz="0 0 0.0544"
      rpy="0 0 0" />
    <parent
      link="base_link" />
    <child
      link="link_1" />
    <axis
      xyz="0 0 -1" />
    <limit
      lower="-2"
      upper="2"
      effort="20"
      velocity="20" />
  </joint>
  <link
    name="link_2">
    <inertial>
      <origin
        xyz="-0.000135356006400576 -0.000143592744303343 0.154185327275859"
        rpy="0 0 0" />
      <mass
        value="0.14159893330227" />
      <inertia
        ixx="0.000701238216467739"
        ixy="1.75871749259131E-07"
        ixz="-6.61089290610882E-06"
        iyy="0.000712581851390796"
        iyz="-1.0951072055554E-06"
        izz="3.2319132579535E-05" />
    </inertial>
    <visual>
      <origin
        xyz="0 0 0"
        rpy="0 0 0" />
      <geometry>
        <mesh
          filename="package://abb_irb_120_description/urdf/meshes_irb_120_grande/link_2.STL" />
      </geometry>
      <material
        name="">
        <color
          rgba="1 1 1 1" />
      </material>
    </visual>
    <collision>
      <origin
        xyz="0 0 0"
        rpy="0 0 0" />
      <geometry>
        <mesh
          filename="package://abb_irb_120_description/urdf/meshes_irb_120_grande/link_2.STL" />
      </geometry>
    </collision>
  </link>
  <joint
    name="joint_2"
    type="revolute">
    <origin
      xyz="0 0 0.18176"
      rpy="0 0 0" />
    <parent
      link="link_1" />
    <child
      link="link_2" />
    <axis
      xyz="-1 0 0" />
    <limit
      lower="-2"
      upper="2"
      effort="20"
      velocity="20" />
  </joint>
  <link
    name="link_3">
    <inertial>
      <origin
        xyz="-0.000795950611778533 -0.0294773138357475 0.0972250924706395"
        rpy="0 0 0" />
      <mass
        value="0.137043250968313" />
      <inertia
        ixx="0.000268451624758152"
        ixy="4.47314417387309E-07"
        ixz="-2.49107925354914E-06"
        iyy="0.000168086695951985"
        iyz="-8.78469683582677E-05"
        izz="0.00013394251957468" />
    </inertial>
    <visual>
      <origin
        xyz="0 0 0"
        rpy="0 0 0" />
      <geometry>
        <mesh
          filename="package://abb_irb_120_description/urdf/meshes_irb_120_grande/link_3.STL" />
      </geometry>
      <material
        name="">
        <color
          rgba="0.792156862745098 0.819607843137255 0.933333333333333 1" />
      </material>
    </visual>
    <collision>
      <origin
        xyz="0 0 0"
        rpy="0 0 0" />
      <geometry>
        <mesh
          filename="package://abb_irb_120_description/urdf/meshes_irb_120_grande/link_3.STL" />
      </geometry>
    </collision>
  </link>
  <joint
    name="joint_3"
    type="revolute">
    <origin
      xyz="0 0 0.21892"
      rpy="-0.7854 0 0" />
    <parent
      link="link_2" />
    <child
      link="link_3" />
    <axis
      xyz="-1 0 0" />
    <limit
      lower="-2"
      upper="2"
      effort="20"
      velocity="20" />
  </joint>
  <link
    name="link_4">
    <inertial>
      <origin
        xyz="0.000101756551848356 -0.000146509192858746 0.142094366745814"
        rpy="0 0 0" />
      <mass
        value="0.136022178444888" />
      <inertia
        ixx="0.000554019952123094"
        ixy="1.69591906695947E-07"
        ixz="3.84212892361328E-07"
        iyy="0.000559373340712624"
        iyz="-9.60742545726795E-07"
        izz="2.69043198091941E-05" />
    </inertial>
    <visual>
      <origin
        xyz="0 0 0"
        rpy="0 0 0" />
      <geometry>
        <mesh
          filename="package://abb_irb_120_description/urdf/meshes_irb_120_grande/link_4.STL" />
      </geometry>
      <material
        name="">
        <color
          rgba="1 1 1 1" />
      </material>
    </visual>
    <collision>
      <origin
        xyz="0 0 0"
        rpy="0 0 0" />
      <geometry>
        <mesh
          filename="package://abb_irb_120_description/urdf/meshes_irb_120_grande/link_4.STL" />
      </geometry>
    </collision>
  </link>
  <joint
    name="joint_4"
    type="revolute">
    <origin
      xyz="-0.0011116 -0.062605 0.11982"
      rpy="-1.0936E-14 -4.7184E-15 -4.7184E-15" />
    <parent
      link="link_3" />
    <child
      link="link_4" />
    <axis
      xyz="0 0 -1" />
    <limit
      lower="-2"
      upper="2"
      effort="20"
      velocity="20" />
  </joint>
  <link
    name="link_5">
    <inertial>
      <origin
        xyz="-0.000663369816313716 0.000137179485501793 0.0656968013933179"
        rpy="0 0 0" />
      <mass
        value="0.0880136991441959" />
      <inertia
        ixx="6.53471799788238E-05"
        ixy="3.16251104150344E-08"
        ixz="-3.61285145594892E-06"
        iyy="5.39730805138255E-05"
        iyz="1.69570004687093E-07"
        izz="3.72211681063045E-05" />
    </inertial>
    <visual>
      <origin
        xyz="0 0 0"
        rpy="0 0 0" />
      <geometry>
        <mesh
          filename="package://abb_irb_120_description/urdf/meshes_irb_120_grande/link_5.STL" />
      </geometry>
      <material
        name="">
        <color
          rgba="1 1 1 1" />
      </material>
    </visual>
    <collision>
      <origin
        xyz="0 0 0"
        rpy="0 0 0" />
      <geometry>
        <mesh
          filename="package://abb_irb_120_description/urdf/meshes_irb_120_grande/link_5.STL" />
      </geometry>
    </collision>
  </link>
  <joint
    name="joint_5"
    type="revolute">
    <origin
      xyz="0 0 0.2001"
      rpy="-7.1054E-15 6.9996E-15 6.9996E-15" />
    <parent
      link="link_4" />
    <child
      link="link_5" />
    <axis
      xyz="-1 0 0" />
    <limit
      lower="-2"
      upper="2"
      effort="20"
      velocity="20" />
  </joint>
  <link
    name="link_6">
    <inertial>
      <origin
        xyz="2.41409294178194E-08 -2.20412191942465E-07 0.0187484882172921"
        rpy="0 0 0" />
      <mass
        value="0.000728753606573652" />
      <inertia
        ixx="2.7112691145136E-08"
        ixy="1.73396101879255E-11"
        ixz="2.38573513059539E-14"
        iyy="2.24283727449418E-08"
        iyz="-2.17065591899303E-13"
        izz="4.80923768776333E-08" />
    </inertial>
    <visual>
      <origin
        xyz="0 0 0"
        rpy="0 0 0" />
      <geometry>
        <mesh
          filename="package://abb_irb_120_description/urdf/meshes_irb_120_grande/link_6.STL" />
      </geometry>
      <material
        name="">
        <color
          rgba="1 1 1 1" />
      </material>
    </visual>
    <collision>
      <origin
        xyz="0 0 0"
        rpy="0 0 0" />
      <geometry>
        <mesh
          filename="package://abb_irb_120_description/urdf/meshes_irb_120_grande/link_6.STL" />
      </geometry>
    </collision>
  </link>
  <joint
    name="joint_6"
    type="revolute">
    <origin
      xyz="-0.0015 -0.010003 0.079246"
      rpy="0 0 3.9443E-31" />
    <parent
      link="link_5" />
    <child
      link="link_6" />
    <axis
      xyz="0 0 -1" />
    <limit
      lower="-2"
      upper="2"
      effort="20"
      velocity="20" />
  </joint>

  <transmission name="tran1">
    <type>transmission_interface/SimpleTransmission</type>
    <joint name="joint_1">
      <hardwareInterface>PositionJointInterface</hardwareInterface>
    </joint>
    <actuator name="motor1">
      <mechanicalReduction>1</mechanicalReduction>
    </actuator>
  </transmission>
  <transmission name="tran2">
    <type>transmission_interface/SimpleTransmission</type>
    <joint name="joint_2">
      <hardwareInterface>PositionJointInterface</hardwareInterface>
    </joint>
    <actuator name="motor2">
      <mechanicalReduction>1</mechanicalReduction>
    </actuator>
  </transmission>
  <transmission name="tran3">
    <type>transmission_interface/SimpleTransmission</type>
    <joint name="joint_3">
      <hardwareInterface>PositionJointInterface</hardwareInterface>
    </joint>
    <actuator name="motor3">
      <mechanicalReduction>1</mechanicalReduction>
    </actuator>
  </transmission>
  <transmission name="tran4">
    <type>transmission_interface/SimpleTransmission</type>
    <joint name="joint_4">
      <hardwareInterface>PositionJointInterface</hardwareInterface>
    </joint>
    <actuator name="motor4">
      <mechanicalReduction>1</mechanicalReduction>
    </actuator>
  </transmission>
  <transmission name="tran5">
    <type>transmission_interface/SimpleTransmission</type>
    <joint name="joint_5">
      <hardwareInterface>PositionJointInterface</hardwareInterface>
    </joint>
    <actuator name="motor5">
      <mechanicalReduction>1</mechanicalReduction>
    </actuator>
  </transmission>
  <transmission name="tran6">
    <type>transmission_interface/SimpleTransmission</type>
    <joint name="joint_6">
      <hardwareInterface>PositionJointInterface</hardwareInterface>
    </joint>
    <actuator name="motor6">
      <mechanicalReduction>1</mechanicalReduction>
    </actuator>
  </transmission>
  <!-- end of transmission list -->

  <!-- Gazebo-specific link properties -->
  <gazebo reference="base_link">
    <material>Gazebo/Orange</material>
    <turnGravityOff>true</turnGravityOff>
  </gazebo>
  <gazebo reference="link_1">
    <material>Gazebo/Orange</material>
    <turnGravityOff>true</turnGravityOff>
  </gazebo>
  <gazebo reference="link_2">
    <material>Gazebo/Orange</material>
    <turnGravityOff>true</turnGravityOff>
  </gazebo>  
  <gazebo reference="link_3">
    <material>Gazebo/Orange</material>
    <turnGravityOff>true</turnGravityOff>
  </gazebo>
  <gazebo reference="link_4">
    <material>Gazebo/Orange</material>
    <turnGravityOff>true</turnGravityOff>
  </gazebo>
  <gazebo reference="link_5">
    <material>Gazebo/Orange</material>
    <turnGravityOff>true</turnGravityOff>
  </gazebo>
  <gazebo reference="link_6">
    <material>Gazebo/Black</material>
    <turnGravityOff>true</turnGravityOff>
  </gazebo>

  <!-- ros_control plugin -->
  <gazebo>
    <plugin name="gazebo_ros_control" filename="libgazebo_ros_control.so">
      <robotNamespace>/</robotNamespace>
      <robotSimType>gazebo_ros_control/DefaultRobotHWSim</robotSimType>
    </plugin>
  </gazebo>  
</robot>
