<robot
  name="irb120_peq">

<link name="world"/>
  <joint name="world-base_link-fixed" type="fixed">
    <parent link="world"/>
    <child link="base_link"/>
  </joint>

  <link
    name="base_link">
    <inertial>
      <origin
        xyz="0.00051296 0.015548 0.022027"
        rpy="0 0 0" />
      <mass
        value="0.27211" />
      <inertia
        ixx="0.00028864"
        ixy="3.1402E-07"
        ixz="-7.434E-07"
        iyy="0.00031302"
        iyz="-2.7862E-05"
        izz="0.00042284" />
    </inertial>
    <visual>
      <origin
        xyz="0 0 0"
        rpy="0 0 0" />
      <geometry>
        <mesh
          filename="package://abb_irb_120_description/urdf/meshes_irb_120_peq/base_link.STL" />
      </geometry>
      <material
        name="">
        <color
          rgba="0.79216 0.81961 0.93333 1" />
      </material>
    </visual>
    <collision>
      <origin
        xyz="0 0 0"
        rpy="0 0 0" />
      <geometry>
        <mesh
          filename="package://abb_irb_120_description/urdf/meshes_irb_120_peq/base_link.STL" />
      </geometry>
    </collision>
  </link>
  <link
    name="link_1">
    <inertial>
      <origin
        xyz="0.00011079 -0.00015953 0.082037"
        rpy="0 0 0" />
      <mass
        value="0.12492" />
      <inertia
        ixx="0.00024086"
        ixy="1.6867E-07"
        ixz="1.4517E-07"
        iyy="0.0002462"
        iyz="-6.166E-07"
        izz="2.6229E-05" />
    </inertial>
    <visual>
      <origin
        xyz="0 0 0"
        rpy="0 0 0" />
      <geometry>
        <mesh
          filename="package://abb_irb_120_description/urdf/meshes_irb_120_peq/link_1.STL" />
      </geometry>
      <material
        name="">
        <color
          rgba="1 1 1 1" />
      </material>
    </visual>
    <collision>
      <origin
        xyz="0 0 0"
        rpy="0 0 0" />
      <geometry>
        <mesh
          filename="package://abb_irb_120_description/urdf/meshes_irb_120_peq/link_1.STL" />
      </geometry>
    </collision>
  </link>
  <joint
    name="joint_1"
    type="revolute">
    <origin
      xyz="0 0 0.0558"
      rpy="0 0 0" />
    <parent
      link="base_link" />
    <child
      link="link_1" />
    <axis
      xyz="0 0 -1" />
    <limit
      lower="-1.5707963"
      upper="1.5707963"
      effort="200000"
      velocity="20000" />
  </joint>
  <link
    name="link_2">
    <inertial>
      <origin
        xyz="0.00096551 -0.00015034 0.11098"
        rpy="0 0 0" />
      <mass
        value="0.13255" />
      <inertia
        ixx="0.00033171"
        ixy="1.7564E-07"
        ixz="-4.3426E-06"
        iyy="0.00034731"
        iyz="-7.4516E-07"
        izz="3.5559E-05" />
    </inertial>
    <visual>
      <origin
        xyz="0 0 0"
        rpy="0 0 0" />
      <geometry>
        <mesh
          filename="package://abb_irb_120_description/urdf/meshes_irb_120_peq/link_2.STL" />
      </geometry>
      <material
        name="">
        <color
          rgba="0.21961 0.21961 0.21961 1" />
      </material>
    </visual>
    <collision>
      <origin
        xyz="0 0 0"
        rpy="0 0 0" />
      <geometry>
        <mesh
          filename="package://abb_irb_120_description/urdf/meshes_irb_120_peq/link_2.STL" />
      </geometry>
    </collision>
  </link>
  <joint
    name="joint_2"
    type="revolute">
    <origin
      xyz="0 0 0.12277"
      rpy="0 0 0" />
    <parent
      link="link_1" />
    <child
      link="link_2" />
    <axis
      xyz="-1 0 0" />
    <limit
      lower="-1.5707963"
      upper="1.5707963"
      effort="200000"
      velocity="20000"  />
  </joint>
  <link
    name="link_3">
    <inertial>
      <origin
        xyz="0.0015375 0.079158 0.030273"
        rpy="0 0 0" />
      <mass
        value="0.13311" />
      <inertia
        ixx="0.00021874"
        ixy="-3.1485E-06"
        ixz="-9.0234E-07"
        iyy="0.00013391"
        iyz="7.1499E-05"
        izz="0.00012703" />
    </inertial>
    <visual>
      <origin
        xyz="0 0 0"
        rpy="0 0 0" />
      <geometry>
        <mesh
          filename="package://abb_irb_120_description/urdf/meshes_irb_120_peq/link_3.STL" />
      </geometry>
      <material
        name="">
        <color
          rgba="0.21961 0.21961 0.21961 1" />
      </material>
    </visual>
    <collision>
      <origin
        xyz="0 0 0"
        rpy="0 0 0" />
      <geometry>
        <mesh
          filename="package://abb_irb_120_description/urdf/meshes_irb_120_peq/link_3.STL" />
      </geometry>
    </collision>
  </link>
  <joint
    name="joint_3"
    type="revolute">
    <origin
      xyz="0 0 0.15826"
      rpy="0.7854 0 7.2249E-15" />
    <parent
      link="link_2" />
    <child
      link="link_3" />
    <axis
      xyz="-1 0 0" />
    <limit
     lower="-1.5707963"
      upper="1.5707963"
      effort="200000"
      velocity="20000"  />
  </joint>
  <link
    name="link_4">
    <inertial>
      <origin
        xyz="0.00011113 0.10829 0.00016001"
        rpy="0 0 0" />
      <mass
        value="0.12454" />
      <inertia
        ixx="0.00023558"
        ixy="1.3957E-07"
        ixz="-1.3074E-07"
        iyy="2.6051E-05"
        iyz="6.0854E-07"
        izz="0.00024095" />
    </inertial>
    <visual>
      <origin
        xyz="0 0 0"
        rpy="0 0 0" />
      <geometry>
        <mesh
          filename="package://abb_irb_120_description/urdf/meshes_irb_120_peq/link_4.STL" />
      </geometry>
      <material
        name="">
        <color
          rgba="1 1 1 1" />
      </material>
    </visual>
    <collision>
      <origin
        xyz="0 0 0"
        rpy="0 0 0" />
      <geometry>
        <mesh
          filename="package://abb_irb_120_description/urdf/meshes_irb_120_peq/link_4.STL" />
      </geometry>
    </collision>
  </link>
  <joint
    name="joint_4"
    type="revolute">
    <origin
      xyz="0.0011084 0.092995 0.062475"
      rpy="0 0 0" />
    <parent
      link="link_3" />
    <child
      link="link_4" />
    <axis
      xyz="0 -1 0" />
    <limit
      lower="-1.5707963"
      upper="1.5707963"
      effort="200000"
      velocity="20000"  />
  </joint>
  <link
    name="link_5">
    <inertial>
      <origin
        xyz="0.00039869 0.063728 -0.00013307"
        rpy="0 0 0" />
      <mass
        value="0.092614" />
      <inertia
        ixx="7.3178E-05"
        ixy="-3.2958E-06"
        ixz="-3.2165E-08"
        iyy="4.1616E-05"
        iyz="-1.9586E-07"
        izz="6.6047E-05" />
    </inertial>
    <visual>
      <origin
        xyz="0 0 0"
        rpy="0 0 0" />
      <geometry>
        <mesh
          filename="package://abb_irb_120_description/urdf/meshes_irb_120_peq/link_5.STL" />
      </geometry>
      <material
        name="">
        <color
          rgba="0.21961 0.21961 0.21961 1" />
      </material>
    </visual>
    <collision>
      <origin
        xyz="0 0 0"
        rpy="0 0 0" />
      <geometry>
        <mesh
          filename="package://abb_irb_120_description/urdf/meshes_irb_120_peq/link_5.STL" />
      </geometry>
    </collision>
  </link>
  <joint
    name="joint_5"
    type="revolute">
    <origin
      xyz="0 0.14861 0"
      rpy="-1.2768E-15 4.1417E-16 4.1417E-16" />
    <parent
      link="link_4" />
    <child
      link="link_5" />
    <axis
      xyz="-1 0 0" />
    <limit
       lower="-1.5707963"
      upper="1.5707963"
      effort="200000"
      velocity="20000" />
  </joint>
  <link
    name="link_6">
    <inertial>
      <origin
        xyz="1.9446E-08 0.034809 -8.7414E-08"
        rpy="0 0 0" />
      <mass
        value="0.0018612" />
      <inertia
        ixx="2.8099E-07"
        ixy="7.6219E-14"
        ixz="1.1843E-07"
        iyy="3.4976E-07"
        iyz="-3.8364E-13"
        izz="8.0474E-08" />
    </inertial>
    <visual>
      <origin
        xyz="0 0 0"
        rpy="0 0 0" />
      <geometry>
        <mesh
          filename="package://abb_irb_120_description/urdf/meshes_irb_120_peq/link_6.STL" />
      </geometry>
      <material
        name="">
        <color
          rgba="0.21961 0.21961 0.21961 1" />
      </material>
    </visual>
    <collision>
      <origin
        xyz="0 0 0"
        rpy="0 0 0" />
      <geometry>
        <mesh
          filename="package://abb_irb_120_description/urdf/meshes_irb_120_peq/link_6.STL" />
      </geometry>
    </collision>
  </link>
  <joint
    name="joint_6"
    type="revolute">
    <origin
      xyz="-0.00039 0.064507 0.01"
      rpy="0 0 -7.8886E-31" />
    <parent
      link="link_5" />
    <child
      link="link_6" />
    <axis
      xyz="0 -1 0" />
    <limit
        lower="-1.5707963"
      upper="1.5707963"
      effort="200000"
      velocity="20000"  />
  </joint>

  <transmission name="tran1">
    <type>transmission_interface/SimpleTransmission</type>
    <joint name="joint_1">
      <hardwareInterface>PositionJointInterface</hardwareInterface>
    </joint>
    <actuator name="motor1">
      <mechanicalReduction>1</mechanicalReduction>
    </actuator>
  </transmission>
  <transmission name="tran2">
    <type>transmission_interface/SimpleTransmission</type>
    <joint name="joint_2">
      <hardwareInterface>PositionJointInterface</hardwareInterface>
    </joint>
    <actuator name="motor2">
      <mechanicalReduction>1</mechanicalReduction>
    </actuator>
  </transmission>
  <transmission name="tran3">
    <type>transmission_interface/SimpleTransmission</type>
    <joint name="joint_3">
      <hardwareInterface>PositionJointInterface</hardwareInterface>
    </joint>
    <actuator name="motor3">
      <mechanicalReduction>1</mechanicalReduction>
    </actuator>
  </transmission>
  <transmission name="tran4">
    <type>transmission_interface/SimpleTransmission</type>
    <joint name="joint_4">
      <hardwareInterface>PositionJointInterface</hardwareInterface>
    </joint>
    <actuator name="motor4">
      <mechanicalReduction>1</mechanicalReduction>
    </actuator>
  </transmission>
  <transmission name="tran5">
    <type>transmission_interface/SimpleTransmission</type>
    <joint name="joint_5">
      <hardwareInterface>PositionJointInterface</hardwareInterface>
    </joint>
    <actuator name="motor5">
      <mechanicalReduction>1</mechanicalReduction>
    </actuator>
  </transmission>
  <transmission name="tran6">
    <type>transmission_interface/SimpleTransmission</type>
    <joint name="joint_6">
      <hardwareInterface>PositionJointInterface</hardwareInterface>
    </joint>
    <actuator name="motor6">
      <mechanicalReduction>1</mechanicalReduction>
    </actuator>
  </transmission>
  <!-- end of transmission list -->

  <!-- Gazebo-specific link properties -->
  <gazebo reference="base_link">
    <material>Gazebo/Orange</material>
    <turnGravityOff>true</turnGravityOff>
  </gazebo>
  <gazebo reference="link_1">
    <material>Gazebo/Orange</material>
    <turnGravityOff>true</turnGravityOff>
  </gazebo>
  <gazebo reference="link_2">
    <material>Gazebo/Orange</material>
    <turnGravityOff>true</turnGravityOff>
  </gazebo>  
  <gazebo reference="link_3">
    <material>Gazebo/Orange</material>
    <turnGravityOff>true</turnGravityOff>
  </gazebo>
  <gazebo reference="link_4">
    <material>Gazebo/Orange</material>
    <turnGravityOff>true</turnGravityOff>
  </gazebo>
  <gazebo reference="link_5">
    <material>Gazebo/Orange</material>
    <turnGravityOff>true</turnGravityOff>
  </gazebo>
  <gazebo reference="link_6">
    <material>Gazebo/Black</material>
    <turnGravityOff>true</turnGravityOff>
  </gazebo>

  <!-- ros_control plugin -->
  <gazebo>
    <plugin name="gazebo_ros_control" filename="libgazebo_ros_control.so">
      <robotNamespace>/</robotNamespace>
      <robotSimType>gazebo_ros_control/DefaultRobotHWSim</robotSimType>
    </plugin>
  </gazebo>  
</robot>
